Workbook

Sheet BEHAVIOURABILITY
A1: TASK | B1: Decision Making | C1: Self-Management | D1: Communication | E1: Engagement
A2: TASK T1 Selezionare un periodo storico | B2: SE, K&S
A3: TASK T2 Avviare una conversazione | B3: SE, K&S | D3: SE, MOT | E3: MOT
A4: TASK T3 Condurre una conversazione con un personaggio | D4: SE, MOT | E4: MOT, K&S
A5: TASK T4 Partecipare a quiz | B5: K&S | C5: PC, MOT | E5: MOT, K&S
A6: TASK T5 Salvare o rivedere una conversazione utile | C6: PC, K&S
A7: TASK T6 Condividere una conversazione con compagni o insegnanti | D7: SE, MOT
A8: TASK T7 Ricevere feedback e premi virtuali | B8: K&S | C8: PC, MOT | E8: MOT, K&S
A9: TASK T8 Visualizzare le domande assegnate dall'insegnante | B9: SE, K&S | C9: PC, MOT
A10: TASK T9 Creare una classe virtuale | B10: SE, K&S | C10: PC, MOT
A11: TASK T10 Assegnare domande alla classe | B11: SE, K&S | C11: PC
A12: TASK T11 Partecipare ad una classe virtuale | B12: SE, K&S | C12: PC | D12: SE, MOT | E12: MOT, K&S
A13: TASK T12 Seguire lo studio del figlio | B13: PC | C13: PC | E13: MOT
A14: Legenda
A15: SE = Self-Efficacy
A16: K&S = Knowledge & Skills
A17: PC = Personal Control
A18: MOT = Motivation

Sheet Utente1
B1: Self Efficacy | C1: Scarso | D1: Sufficiente | E1: Buono | F1: Molto Buono | G1: Eccellente | H1: Valore
A2: T1_SE1 | B2: Ti sei sentito più sicuro nel scegliere un periodo storico usando le anteprime con immagine? | F2: x | H2: =IF(C2="X",1)+IF(D2="X",2)+IF(E2="X",3)+IF(F2="X",4)+IF(G2="X",5) -> 4
A3: T1_SE2 | B3: L'icona o la miniatura del periodo storico ti ha aiutato a selezionarlo con facilità? | F3: x | H3: =IF(C3="X",1)+IF(D3="X",2)+IF(E3="X",3)+IF(F3="X",4)+IF(G3="X",5) -> 4
B4: Knowledge&Skills
A5: T1_KS1 | B5: Sei riuscito a distinguere rapidamente i periodi storici grazie alle immagini e alle etichette? | E5: x | H5: =IF(C5="X",1)+IF(D5="X",2)+IF(E5="X",3)+IF(F5="X",4)+IF(G5="X",5) -> 3
B7: Self Efficacy
A8: T2_SE1 | B8: Quanto la biografia ti ha permesso di scegliere di avviare la conversazione?
A9: T2_SE2 | B9: Ti sei sentito sicuro nel cliccare sul pulsante 'Avvia conversazione' per parlare con il personaggio? | F9: x | H9: =IF(C9="X",1)+IF(D9="X",2)+IF(E9="X",3)+IF(F9="X",4)+IF(G9="X",5) -> 4
B10: Knowledge&Skills
A11: T2_KS1 | B11: Sai come avviare una conversazione? | G11: x | H11: =IF(C11="X",1)+IF(D11="X",2)+IF(E11="X",3)+IF(F11="X",4)+IF(G11="X",5) -> 5
B12: Motivation
A13: T2_MOT1 | B13: Quanto ti ha motivato la lettura della biografia del personaggio? | G13: x | H13: =IF(C13="X",1)+IF(D13="X",2)+IF(E13="X",3)+IF(F13="X",4)+IF(G13="X",5) -> 5
A14: T2_MOT2 | B14: L'immagine del personaggio ti ha motivato nell'avviare la conversazione? | F14: x | H14: =IF(C14="X",1)+IF(D14="X",2)+IF(E14="X",3)+IF(F14="X",4)+IF(G14="X",5) -> 4
B16: Self Efficacy
A17: T3_SE1 | B17: Durante la conversazione, ti sei sentito sicuro nell'inviare messaggi usando il campo di testo?
A18: T3_SE2 | B18: Durante la conversazione, ti sei sentito sicuro nell'inviare messaggi usando la registrazione vocale? | G18: x | H18: =IF(C18="X",1)+IF(D18="X",2)+IF(E18="X",3)+IF(F18="X",4)+IF(G18="X",5) -> 5
A19: T3_SE3 | B19: Ti è stato facile capire quale pulsante premere per far parlare di nuovo il personaggio? | F19: x | H19: =IF(C19="X",1)+IF(D19="X",2)+IF(E19="X",3)+IF(F19="X",4)+IF(G19="X",5) -> 4
A20: T3_SE4 | B20: Il pulsante 'microfono' era chiaro?
B21: Knowledge&Skills
A22: T3_KS1 | B22: Quanto sei in grado di passare dalla tastiera alla dettatura vocale quando conversi con il personaggio? | F22: x | H22: =IF(C22="X",1)+IF(D22="X",2)+IF(E22="X",3)+IF(F22="X",4)+IF(G22="X",5) -> 4
B23: Motivation
A24: T3_MOT1 | B24: I feedback del personaggio (es. emoji, suoni) ti hanno motivato a continuare la conversazione? | G24: x | H24: =IF(C24="X",1)+IF(D24="X",2)+IF(E24="X",3)+IF(F24="X",4)+IF(G24="X",5) -> 5
B26: Knowledge&Skills
A27: T4_KS1 | B27: Sai come usare il pulsante 'Prossima domanda' per navigare nel quiz? | G27: x | H27: =IF(C27="X",1)+IF(D27="X",2)+IF(E27="X",3)+IF(F27="X",4)+IF(G27="X",5) -> 5
A28: T4_KS2 | B28: Sai quante domande restanti ci sono, mentre esegui un quiz?
B29: Personal Control
A30: T4_PC1 | B30: Hai avuto la percezione di poter uscire dal quiz se necessario usando l'icona appropriata? | F30: x | H30: =IF(C30="X",1)+IF(D30="X",2)+IF(E30="X",3)+IF(F30="X",4)+IF(G30="X",5) -> 4
A31: T4_PC2 | B31: Hai avuto la percezione di star migliorando eseguendo il quiz? | F31: x | H31: =IF(C31="X",1)+IF(D31="X",2)+IF(E31="X",3)+IF(F31="X",4)+IF(G31="X",5) -> 4
B32: Motivation
A33: T4_MOT1 | B33: La barra di progresso del quiz ti ha motivato a completare tutte le domande? | G33: x | H33: =IF(C33="X",1)+IF(D33="X",2)+IF(E33="X",3)+IF(F33="X",4)+IF(G33="X",5) -> 5
A34: T4_MOT2 | B34: I feedback ottenuti al controllo di ogni risposta ti hanno motivato nel continuare il quiz? | G34: x | H34: =IF(C34="X",1)+IF(D34="X",2)+IF(E34="X",3)+IF(F34="X",4)+IF(G34="X",5) -> 5
A35: T4_MOT3 | B35: I feedback al termine del quiz, ti hanno motivato a iniziare un nuovo quiz? | E35: x | H35: =IF(C35="X",1)+IF(D35="X",2)+IF(E35="X",3)+IF(F35="X",4)+IF(G35="X",5) -> 3
B37: Knowledge&Skills
A38: T5_KS1 | B38: Sai come etichettare o rinominare le conversazioni salvate per ritrovarle più facilmente? | F38: x | H38: =IF(C38="X",1)+IF(D38="X",2)+IF(E38="X",3)+IF(F38="X",4)+IF(G38="X",5) -> 4
A39: T5_KS2 | B39: Comprendi il significato delle icone per il salvataggio e la condivisione di una conversazione? | G39: x | H39: =IF(C39="X",1)+IF(D39="X",2)+IF(E39="X",3)+IF(F39="X",4)+IF(G39="X",5) -> 5
B40: Personal Control
A41: T5_PC1 | B41: Ti senti libero di eliminare una conversazione salvata tramite il menu contestuale? | E41: x | H41: =IF(C41="X",1)+IF(D41="X",2)+IF(E41="X",3)+IF(F41="X",4)+IF(G41="X",5) -> 3
A42: T5_PC2 | B42: Ti senti in grado di scegliere quali conversazioni siano utili da salvare o condividere? | F42: x | H42: =IF(C42="X",1)+IF(D42="X",2)+IF(E42="X",3)+IF(F42="X",4)+IF(G42="X",5) -> 4
A43: T5_PC3 | B43: Il salvataggio di una conversazione ti è sembrato evidente? | H43: =IF(C43="X",1)+IF(D43="X",2)+IF(E43="X",3)+IF(F43="X",4)+IF(G43="X",5) -> 0
B45: Self Efficacy
...

Sheet Utente2
B1: Self Efficacy | C1: Scarso | D1: Sufficiente | E1: Buono | F1: Molto Buono | G1: Eccellente | H1: Valore
A2: T1_SE1 | B2: Ti sei sentito più sicuro nel scegliere un periodo storico usando le anteprime con immagine? | D2: x | H2: =IF(C2="X",1)+IF(D2="X",2)+IF(E2="X",3)+IF(F2="X",4)+IF(G2="X",5) -> 2
A3: T1_SE2 | B3: L'icona o la miniatura del periodo storico ti ha aiutato a selezionarlo con facilità? | E3: x | H3: =IF(C3="X",1)+IF(D3="X",2)+IF(E3="X",3)+IF(F3="X",4)+IF(G3="X",5) -> 3
B4: Knowledge&Skills
A5: T1_KS1 | B5: Sei riuscito a distinguere rapidamente i periodi storici grazie alle immagini e alle etichette? | F5: x | H5: =IF(C5="X",1)+IF(D5="X",2)+IF(E5="X",3)+IF(F5="X",4)+IF(G5="X",5) -> 4
B7: Self Efficacy
A8: T2_SE1 | B8: Quanto la biografia ti ha permesso di scegliere di avviare la conversazione? | F8: x | H8: =IF(C8="X",1)+IF(D8="X",2)+IF(E8="X",3)+IF(F8="X",4)+IF(G8="X",5) -> 4
A9: T2_SE2 | B9: Ti sei sentito sicuro nel cliccare sul pulsante 'Avvia conversazione' per parlare con il personaggio? | D9: x | H9: =IF(C9="X",1)+IF(D9="X",2)+IF(E9="X",3)+IF(F9="X",4)+IF(G9="X",5) -> 2
B10: Knowledge&Skills
A11: T2_KS1 | B11: Sai come avviare una conversazione? | G11: x | H11: =IF(C11="X",1)+IF(D11="X",2)+IF(E11="X",3)+IF(F11="X",4)+IF(G11="X",5) -> 5
B12: Motivation
A13: T2_MOT1 | B13: Quanto ti ha motivato la lettura della biografia del personaggio? | F13: x | H13: =IF(C13="X",1)+IF(D13="X",2)+IF(E13="X",3)+IF(F13="X",4)+IF(G13="X",5) -> 4
A14: T2_MOT2 | B14: L'immagine del personaggio ti ha motivato nell'avviare la conversazione? | G14: x | H14: =IF(C14="X",1)+IF(D14="X",2)+IF(E14="X",3)+IF(F14="X",4)+IF(G14="X",5) -> 5
B16: Self Efficacy
A17: T3_SE1 | B17: Durante la conversazione, ti sei sentito sicuro nell'inviare messaggi usando il campo di testo? | F17: x | H17: =IF(C17="X",1)+IF(D17="X",2)+IF(E17="X",3)+IF(F17="X",4)+IF(G17="X",5) -> 4
A18: T3_SE2 | B18: Durante la conversazione, ti sei sentito sicuro nell'inviare messaggi usando la registrazione vocale? | E18: x | H18: =IF(C18="X",1)+IF(D18="X",2)+IF(E18="X",3)+IF(F18="X",4)+IF(G18="X",5) -> 3
A19: T3_SE3 | B19: Ti è stato facile capire quale pulsante premere per far parlare di nuovo il personaggio? | E19: x | H19: =IF(C19="X",1)+IF(D19="X",2)+IF(E19="X",3)+IF(F19="X",4)+IF(G19="X",5) -> 3
A20: T3_SE4 | B20: Il pulsante 'microfono' era chiaro? | E20: x | H20: =IF(C20="X",1)+IF(D20="X",2)+IF(E20="X",3)+IF(F20="X",4)+IF(G20="X",5) -> 3
B21: Knowledge&Skills
A22: T3_KS1 | B22: Quanto sei in grado di passare dalla tastiera alla dettatura vocale quando conversi con il personaggio? | F22: x | H22: =IF(C22="X",1)+IF(D22="X",2)+IF(E22="X",3)+IF(F22="X",4)+IF(G22="X",5) -> 4
B23: Motivation
A24: T3_MOT1 | B24: I feedback del personaggio (es. emoji, suoni) ti hanno motivato a continuare la conversazione? | D24: x | H24: =IF(C24="X",1)+IF(D24="X",2)+IF(E24="X",3)+IF(F24="X",4)+IF(G24="X",5) -> 2
B26: Knowledge&Skills
A27: T4_KS1 | B27: Sai come usare il pulsante 'Prossima domanda' per navigare nel quiz? | F27: x | H27: =IF(C27="X",1)+IF(D27="X",2)+IF(E27="X",3)+IF(F27="X",4)+IF(G27="X",5) -> 4
A28: T4_KS2 | B28: Sai quante domande restanti ci sono, mentre esegui un quiz? | G28: x | H28: =IF(C28="X",1)+IF(D28="X",2)+IF(E28="X",3)+IF(F28="X",4)+IF(G28="X",5) -> 5
B29: Personal Control
A30: T4_PC1 | B30: Hai avuto la percezione di poter uscire dal quiz se necessario usando l'icona appropriata? | E30: x | H30: =IF(C30="X",1)+IF(D30="X",2)+IF(E30="X",3)+IF(F30="X",4)+IF(G30="X",5) -> 3
A31: T4_PC2 | B31: Hai avuto la percezione di star migliorando eseguendo il quiz? | E31: x | H31: =IF(C31="X",1)+IF(D31="X",2)+IF(E31="X",3)+IF(F31="X",4)+IF(G31="X",5) -> 3
B32: Motivation
A33: T4_MOT1 | B33: La barra di progresso del quiz ti ha motivato a completare tutte le domande? | E33: x | H33: =IF(C33="X",1)+IF(D33="X",2)+IF(E33="X",3)+IF(F33="X",4)+IF(G33="X",5) -> 3
A34: T4_MOT2 | B34: I feedback ottenuti al controllo di ogni risposta ti hanno motivato nel continuare il quiz? | E34: x | H34: =IF(C34="X",1)+IF(D34="X",2)+IF(E34="X",3)+IF(F34="X",4)+IF(G34="X",5) -> 3
A35: T4_MOT3 | B35: I feedback al termine del quiz, ti hanno motivato a iniziare un nuovo quiz? | F35: x | H35: =IF(C35="X",1)+IF(D35="X",2)+IF(E35="X",3)+IF(F35="X",4)+IF(G35="X",5) -> 4
B37: Knowledge&Skills
A38: T5_KS1 | B38: Sai come etichettare o rinominare le conversazioni salvate per ritrovarle più facilmente? | F38: x | H38: =IF(C38="X",1)+IF(D38="X",2)+IF(E38="X",3)+IF(F38="X",4)+IF(G38="X",5) -> 4
A39: T5_KS2 | B39: Comprendi il significato delle icone per il salvataggio e la condivisione di una conversazione? | G39: x | H39: =IF(C39="X",1)+IF(D39="X",2)+IF(E39="X",3)+IF(F39="X",4)+IF(G39="X",5) -> 5
B40: Personal Control
A41: T5_PC1 | B41: Ti senti libero di eliminare una conversazione salvata tramite il menu contestuale? | D41: x | H41: =IF(C41="X",1)+IF(D41="X",2)+IF(E41="X",3)+IF(F41="X",4)+IF(G41="X",5) -> 2
A42: T5_PC2 | B42: Ti senti in grado di scegliere quali conversazioni siano utili da salvare o condividere? | F42: x | H42: =IF(C42="X",1)+IF(D42="X",2)+IF(E42="X",3)+IF(F42="X",4)+IF(G42="X",5) -> 4
A43: T5_PC3 | B43: Il salvataggio di una conversazione ti è sembrato evidente? | G43: x | H43: =IF(C43="X",1)+IF(D43="X",2)+IF(E43="X",3)+IF(F43="X",4)+IF(G43="X",5) -> 5
B45: Self Efficacy
...

Sheet Utente3
B1: Self Efficacy | C1: Scarso | D1: Sufficiente | E1: Buono | F1: Molto Buono | G1: Eccellente | H1: Valore
A2: T1_SE1 | B2: Ti sei sentito più sicuro nel scegliere un periodo storico usando le anteprime con immagine? | F2: x | H2: =IF(C2="X",1)+IF(D2="X",2)+IF(E2="X",3)+IF(F2="X",4)+IF(G2="X",5) -> 4
A3: T1_SE2 | B3: L'icona o la miniatura del periodo storico ti ha aiutato a selezionarlo con facilità? | F3: x | H3: =IF(C3="X",1)+IF(D3="X",2)+IF(E3="X",3)+IF(F3="X",4)+IF(G3="X",5) -> 4
B4: Knowledge&Skills
A5: T1_KS1 | B5: Sei riuscito a distinguere rapidamente i periodi storici grazie alle immagini e alle etichette? | E5: x | H5: =IF(C5="X",1)+IF(D5="X",2)+IF(E5="X",3)+IF(F5="X",4)+IF(G5="X",5) -> 3
B7: Self Efficacy
A8: T2_SE1 | B8: Quanto la biografia ti ha permesso di scegliere di avviare la conversazione? | G8: x | H8: =IF(C8="X",1)+IF(D8="X",2)+IF(E8="X",3)+IF(F8="X",4)+IF(G8="X",5) -> 5
A9: T2_SE2 | B9: Ti sei sentito sicuro nel cliccare sul pulsante 'Avvia conversazione' per parlare con il personaggio? | E9: x | H9: =IF(C9="X",1)+IF(D9="X",2)+IF(E9="X",3)+IF(F9="X",4)+IF(G9="X",5) -> 3
B10: Knowledge&Skills
A11: T2_KS1 | B11: Sai come avviare una conversazione? | F11: x | H11: =IF(C11="X",1)+IF(D11="X",2)+IF(E11="X",3)+IF(F11="X",4)+IF(G11="X",5) -> 4
B12: Motivation
A13: T2_MOT1 | B13: Quanto ti ha motivato la lettura della biografia del personaggio? | G13: x | H13: =IF(C13="X",1)+IF(D13="X",2)+IF(E13="X",3)+IF(F13="X",4)+IF(G13="X",5) -> 5
A14: T2_MOT2 | B14: L'immagine del personaggio ti ha motivato nell'avviare la conversazione? | E14: x | H14: =IF(C14="X",1)+IF(D14="X",2)+IF(E14="X",3)+IF(F14="X",4)+IF(G14="X",5) -> 3
B16: Self Efficacy
A17: T3_SE1 | B17: Durante la conversazione, ti sei sentito sicuro nell'inviare messaggi usando il campo di testo? | G17: x | H17: =IF(C17="X",1)+IF(D17="X",2)+IF(E17="X",3)+IF(F17="X",4)+IF(G17="X",5) -> 5
A18: T3_SE2 | B18: Durante la conversazione, ti sei sentito sicuro nell'inviare messaggi usando la registrazione vocale? | G18: x | H18: =IF(C18="X",1)+IF(D18="X",2)+IF(E18="X",3)+IF(F18="X",4)+IF(G18="X",5) -> 5
A19: T3_SE3 | B19: Ti è stato facile capire quale pulsante premere per far parlare di nuovo il personaggio? | E19: x | H19: =IF(C19="X",1)+IF(D19="X",2)+IF(E19="X",3)+IF(F19="X",4)+IF(G19="X",5) -> 3
A20: T3_SE4 | B20: Il pulsante 'microfono' era chiaro? | E20: x | H20: =IF(C20="X",1)+IF(D20="X",2)+IF(E20="X",3)+IF(F20="X",4)+IF(G20="X",5) -> 3
B21: Knowledge&Skills
A22: T3_KS1 | B22: Quanto sei in grado di passare dalla tastiera alla dettatura vocale quando conversi con il personaggio? | E22: x | H22: =IF(C22="X",1)+IF(D22="X",2)+IF(E22="X",3)+IF(F22="X",4)+IF(G22="X",5) -> 3
B23: Motivation
A24: T3_MOT1 | B24: I feedback del personaggio (es. emoji, suoni) ti hanno motivato a continuare la conversazione? | F24: x | H24: =IF(C24="X",1)+IF(D24="X",2)+IF(E24="X",3)+IF(F24="X",4)+IF(G24="X",5) -> 4
B26: Knowledge&Skills
A27: T4_KS1 | B27: Sai come usare il pulsante per la prossima domanda, per navigare nel quiz? | E27: x | H27: =IF(C27="X",1)+IF(D27="X",2)+IF(E27="X",3)+IF(F27="X",4)+IF(G27="X",5) -> 3
A28: T4_KS2 | B28: Sai quante domande restanti ci sono, mentre esegui un quiz? | G28: x | H28: =IF(C28="X",1)+IF(D28="X",2)+IF(E28="X",3)+IF(F28="X",4)+IF(G28="X",5) -> 5
B29: Personal Control
A30: T4_PC1 | B30: Hai avuto la percezione di poter uscire dal quiz se necessario usando l'icona appropriata? | E30: x | H30: =IF(C30="X",1)+IF(D30="X",2)+IF(E30="X",3)+IF(F30="X",4)+IF(G30="X",5) -> 3
A31: T4_PC2 | B31: Hai avuto la percezione di star migliorando eseguendo il quiz? | G31: x | H31: =IF(C31="X",1)+IF(D31="X",2)+IF(E31="X",3)+IF(F31="X",4)+IF(G31="X",5) -> 5
B32: Motivation
A33: T4_MOT1 | B33: La barra di progresso del quiz ti ha motivato a completare tutte le domande? | F33: x | H33: =IF(C33="X",1)+IF(D33="X",2)+IF(E33="X",3)+IF(F33="X",4)+IF(G33="X",5) -> 4
A34: T4_MOT2 | B34: I feedback ottenuti al controllo di ogni risposta ti hanno motivato nel continuare il quiz? | F34: x | H34: =IF(C34="X",1)+IF(D34="X",2)+IF(E34="X",3)+IF(F34="X",4)+IF(G34="X",5) -> 4
A35: T4_MOT3 | B35: I feedback al termine del quiz, ti hanno motivato a iniziare un nuovo quiz? | F35: x | H35: =IF(C35="X",1)+IF(D35="X",2)+IF(E35="X",3)+IF(F35="X",4)+IF(G35="X",5) -> 4
B37: Knowledge&Skills
A38: T5_KS1 | B38: Sai come etichettare o rinominare le conversazioni salvate per ritrovarle più facilmente? | E38: x | H38: =IF(C38="X",1)+IF(D38="X",2)+IF(E38="X",3)+IF(F38="X",4)+IF(G38="X",5) -> 3
A39: T5_KS2 | B39: Comprendi il significato delle icone per il salvataggio e la condivisione di una conversazione? | G39: x | H39: =IF(C39="X",1)+IF(D39="X",2)+IF(E39="X",3)+IF(F39="X",4)+IF(G39="X",5) -> 5
B40: Personal Control
A41: T5_PC1 | B41: Ti senti libero di eliminare una conversazione salvata tramite il menu contestuale? | F41: x | H41: =IF(C41="X",1)+IF(D41="X",2)+IF(E41="X",3)+IF(F41="X",4)+IF(G41="X",5) -> 4
A42: T5_PC2 | B42: Ti senti in grado di scegliere quali conversazioni siano utili da salvare o condividere? | G42: x | H42: =IF(C42="X",1)+IF(D42="X",2)+IF(E42="X",3)+IF(F42="X",4)+IF(G42="X",5) -> 5
A43: T5_PC3 | B43: Il salvataggio di una conversazione ti è sembrato evidente? | G43: x | H43: =IF(C43="X",1)+IF(D43="X",2)+IF(E43="X",3)+IF(F43="X",4)+IF(G43="X",5) -> 5
B45: Self Efficacy
...

Sheet Utente4
B1: Self Efficacy | C1: Scarso | D1: Sufficiente | E1: Buono | F1: Molto Buono | G1: Eccellente | H1: Valore
A2: T1_SE1 | B2: Ti sei sentito più sicuro nel scegliere un periodo storico usando le anteprime con immagine? | F2: x | H2: =IF(C2="X",1)+IF(D2="X",2)+IF(E2="X",3)+IF(F2="X",4)+IF(G2="X",5) -> 4
A3: T1_SE2 | B3: L'icona o la miniatura del periodo storico ti ha aiutato a selezionarlo con facilità? | F3: x | H3: =IF(C3="X",1)+IF(D3="X",2)+IF(E3="X",3)+IF(F3="X",4)+IF(G3="X",5) -> 4
B4: Knowledge&Skills
A5: T1_KS1 | B5: Sei riuscito a distinguere rapidamente i periodi storici grazie alle immagini e alle etichette? | E5: x | H5: =IF(C5="X",1)+IF(D5="X",2)+IF(E5="X",3)+IF(F5="X",4)+IF(G5="X",5) -> 3
B7: Self Efficacy
A8: T2_SE1 | B8: Quanto la biografia ti ha permesso di scegliere di avviare la conversazione? | G8: x | H8: =IF(C8="X",1)+IF(D8="X",2)+IF(E8="X",3)+IF(F8="X",4)+IF(G8="X",5) -> 5
A9: T2_SE2 | B9: Ti sei sentito sicuro nel cliccare sul pulsante 'Avvia conversazione' per parlare con il personaggio? | G9: x | H9: =IF(C9="X",1)+IF(D9="X",2)+IF(E9="X",3)+IF(F9="X",4)+IF(G9="X",5) -> 5
B10: Knowledge&Skills
A11: T2_KS1 | B11: Sai come avviare una conversazione? | G11: x | H11: =IF(C11="X",1)+IF(D11="X",2)+IF(E11="X",3)+IF(F11="X",4)+IF(G11="X",5) -> 5
B12: Motivation
A13: T2_MOT1 | B13: Quanto ti ha motivato la lettura della biografia del personaggio? | G13: x | H13: =IF(C13="X",1)+IF(D13="X",2)+IF(E13="X",3)+IF(F13="X",4)+IF(G13="X",5) -> 5
A14: T2_MOT2 | B14: L'immagine del personaggio ti ha motivato nell'avviare la conversazione? | E14: x | H14: =IF(C14="X",1)+IF(D14="X",2)+IF(E14="X",3)+IF(F14="X",4)+IF(G14="X",5) -> 3
B16: Self Efficacy
A17: T3_SE1 | B17: Durante la conversazione, ti sei sentito sicuro nell'inviare messaggi usando il campo di testo? | G17: x | H17: =IF(C17="X",1)+IF(D17="X",2)+IF(E17="X",3)+IF(F17="X",4)+IF(G17="X",5) -> 5
A18: T3_SE2 | B18: Durante la conversazione, ti sei sentito sicuro nell'inviare messaggi usando la registrazione vocale? | G18: x | H18: =IF(C18="X",1)+IF(D18="X",2)+IF(E18="X",3)+IF(F18="X",4)+IF(G18="X",5) -> 5
A19: T3_SE3 | B19: Ti è stato facile capire quale pulsante premere per far parlare di nuovo il personaggio? | G19: x | H19: =IF(C19="X",1)+IF(D19="X",2)+IF(E19="X",3)+IF(F19="X",4)+IF(G19="X",5) -> 5
A20: T3_SE4 | B20: Il pulsante 'microfono' era chiaro? | E20: x | H20: =IF(C20="X",1)+IF(D20="X",2)+IF(E20="X",3)+IF(F20="X",4)+IF(G20="X",5) -> 3
B21: Knowledge&Skills
A22: T3_KS1 | B22: Quanto sei in grado di passare dalla tastiera alla dettatura vocale quando conversi con il personaggio? | F22: x | H22: =IF(C22="X",1)+IF(D22="X",2)+IF(E22="X",3)+IF(F22="X",4)+IF(G22="X",5) -> 4
B23: Motivation
A24: T3_MOT1 | B24: I feedback del personaggio (es. emoji, suoni) ti hanno motivato a continuare la conversazione? | F24: x | H24: =IF(C24="X",1)+IF(D24="X",2)+IF(E24="X",3)+IF(F24="X",4)+IF(G24="X",5) -> 4
B26: Knowledge&Skills
A27: T4_KS1 | B27: Sai come usare il pulsante per la prossima domanda, per navigare nel quiz? | G27: x | H27: =IF(C27="X",1)+IF(D27="X",2)+IF(E27="X",3)+IF(F27="X",4)+IF(G27="X",5) -> 5
A28: T4_KS2 | B28: Sai quante domande restanti ci sono, mentre esegui un quiz? | F28: x | H28: =IF(C28="X",1)+IF(D28="X",2)+IF(E28="X",3)+IF(F28="X",4)+IF(G28="X",5) -> 4
B29: Personal Control
A30: T4_PC1 | B30: Hai avuto la percezione di poter uscire dal quiz se necessario usando l'icona appropriata? | C30: x | H30: =IF(C30="X",1)+IF(D30="X",2)+IF(E30="X",3)+IF(F30="X",4)+IF(G30="X",5) -> 1
A31: T4_PC2 | B31: Hai avuto la percezione di star migliorando eseguendo il quiz? | E31: x | H31: =IF(C31="X",1)+IF(D31="X",2)+IF(E31="X",3)+IF(F31="X",4)+IF(G31="X",5) -> 3
B32: Motivation
A33: T4_MOT1 | B33: La barra di progresso del quiz ti ha motivato a completare tutte le domande? | D33: x | H33: =IF(C33="X",1)+IF(D33="X",2)+IF(E33="X",3)+IF(F33="X",4)+IF(G33="X",5) -> 2
A34: T4_MOT2 | B34: I feedback ottenuti al controllo di ogni risposta ti hanno motivato nel continuare il quiz? | D34: x | H34: =IF(C34="X",1)+IF(D34="X",2)+IF(E34="X",3)+IF(F34="X",4)+IF(G34="X",5) -> 2
A35: T4_MOT3 | B35: I feedback al termine del quiz, ti hanno motivato a iniziare un nuovo quiz? | F35: x | H35: =IF(C35="X",1)+IF(D35="X",2)+IF(E35="X",3)+IF(F35="X",4)+IF(G35="X",5) -> 4
B37: Knowledge&Skills
A38: T5_KS1 | B38: Sai come etichettare o rinominare le conversazioni salvate per ritrovarle più facilmente? | F38: x | H38: =IF(C38="X",1)+IF(D38="X",2)+IF(E38="X",3)+IF(F38="X",4)+IF(G38="X",5) -> 4
A39: T5_KS2 | B39: Comprendi il significato delle icone per il salvataggio e la condivisione di una conversazione? | F39: x | H39: =IF(C39="X",1)+IF(D39="X",2)+IF(E39="X",3)+IF(F39="X",4)+IF(G39="X",5) -> 4
B40: Personal Control
A41: T5_PC1 | B41: Ti senti libero di eliminare una conversazione salvata tramite il menu contestuale? | E41: x | H41: =IF(C41="X",1)+IF(D41="X",2)+IF(E41="X",3)+IF(F41="X",4)+IF(G41="X",5) -> 3
A42: T5_PC2 | B42: Ti senti in grado di scegliere quali conversazioni siano utili da salvare o condividere? | F42: x | H42: =IF(C42="X",1)+IF(D42="X",2)+IF(E42="X",3)+IF(F42="X",4)+IF(G42="X",5) -> 4
A43: T5_PC3 | B43: Il salvataggio di una conversazione ti è sembrato evidente? | G43: x | H43: =IF(C43="X",1)+IF(D43="X",2)+IF(E43="X",3)+IF(F43="X",4)+IF(G43="X",5) -> 5
B45: Self Efficacy
...

Sheet Utente5
B1: Self Efficacy | C1: Scarso | D1: Sufficiente | E1: Buono | F1: Molto Buono | G1: Eccellente | H1: Valore
A2: T1_SE1 | B2: Ti sei sentito più sicuro nel scegliere un periodo storico usando le anteprime con immagine? | F2: x | H2: =IF(C2="X",1)+IF(D2="X",2)+IF(E2="X",3)+IF(F2="X",4)+IF(G2="X",5) -> 4
A3: T1_SE2 | B3: L'icona o la miniatura del periodo storico ti ha aiutato a selezionarlo con facilità? | F3: x | H3: =IF(C3="X",1)+IF(D3="X",2)+IF(E3="X",3)+IF(F3="X",4)+IF(G3="X",5) -> 4
B4: Knowledge&Skills
A5: T1_KS1 | B5: Sei riuscito a distinguere rapidamente i periodi storici grazie alle immagini e alle etichette? | G5: x | H5: =IF(C5="X",1)+IF(D5="X",2)+IF(E5="X",3)+IF(F5="X",4)+IF(G5="X",5) -> 5
B7: Self Efficacy
A8: T2_SE1 | B8: Quanto la biografia ti ha permesso di scegliere di avviare la conversazione? | F8: x | H8: =IF(C8="X",1)+IF(D8="X",2)+IF(E8="X",3)+IF(F8="X",4)+IF(G8="X",5) -> 4
A9: T2_SE2 | B9: Ti sei sentito sicuro nel cliccare sul pulsante 'Avvia conversazione' per parlare con il personaggio? | F9: x | H9: =IF(C9="X",1)+IF(D9="X",2)+IF(E9="X",3)+IF(F9="X",4)+IF(G9="X",5) -> 4
B10: Knowledge&Skills
A11: T2_KS1 | B11: Sai come avviare una conversazione? | F11: x | H11: =IF(C11="X",1)+IF(D11="X",2)+IF(E11="X",3)+IF(F11="X",4)+IF(G11="X",5) -> 4
B12: Motivation
A13: T2_MOT1 | B13: Quanto ti ha motivato la lettura della biografia del personaggio? | G13: x | H13: =IF(C13="X",1)+IF(D13="X",2)+IF(E13="X",3)+IF(F13="X",4)+IF(G13="X",5) -> 5
A14: T2_MOT2 | B14: L'immagine del personaggio ti ha motivato nell'avviare la conversazione? | E14: x | H14: =IF(C14="X",1)+IF(D14="X",2)+IF(E14="X",3)+IF(F14="X",4)+IF(G14="X",5) -> 3
B16: Self Efficacy
A17: T3_SE1 | B17: Durante la conversazione, ti sei sentito sicuro nell'inviare messaggi usando il campo di testo? | G17: x | H17: =IF(C17="X",1)+IF(D17="X",2)+IF(E17="X",3)+IF(F17="X",4)+IF(G17="X",5) -> 5
A18: T3_SE2 | B18: Durante la conversazione, ti sei sentito sicuro nell'inviare messaggi usando la registrazione vocale? | G18: x | H18: =IF(C18="X",1)+IF(D18="X",2)+IF(E18="X",3)+IF(F18="X",4)+IF(G18="X",5) -> 5
A19: T3_SE3 | B19: Ti è stato facile capire quale pulsante premere per far parlare di nuovo il personaggio? | D19: x | H19: =IF(C19="X",1)+IF(D19="X",2)+IF(E19="X",3)+IF(F19="X",4)+IF(G19="X",5) -> 2
A20: T3_SE4 | B20: Il pulsante 'microfono' era chiaro? | E20: x | H20: =IF(C20="X",1)+IF(D20="X",2)+IF(E20="X",3)+IF(F20="X",4)+IF(G20="X",5) -> 3
B21: Knowledge&Skills
A22: T3_KS1 | B22: Quanto sei in grado di passare dalla tastiera alla dettatura vocale quando conversi con il personaggio? | E22: x | H22: =IF(C22="X",1)+IF(D22="X",2)+IF(E22="X",3)+IF(F22="X",4)+IF(G22="X",5) -> 3
B23: Motivation
A24: T3_MOT1 | B24: I feedback del personaggio (es. emoji, suoni) ti hanno motivato a continuare la conversazione? | F24: x | H24: =IF(C24="X",1)+IF(D24="X",2)+IF(E24="X",3)+IF(F24="X",4)+IF(G24="X",5) -> 4
B26: Knowledge&Skills
A27: T4_KS1 | B27: Sai come usare il pulsante per la prossima domanda, per navigare nel quiz? | F27: x | H27: =IF(C27="X",1)+IF(D27="X",2)+IF(E27="X",3)+IF(F27="X",4)+IF(G27="X",5) -> 4
A28: T4_KS2 | B28: Sai quante domande restanti ci sono, mentre esegui un quiz? | G28: x | H28: =IF(C28="X",1)+IF(D28="X",2)+IF(E28="X",3)+IF(F28="X",4)+IF(G28="X",5) -> 5
B29: Personal Control
A30: T4_PC1 | B30: Hai avuto la percezione di poter uscire dal quiz se necessario usando l'icona appropriata? | E30: x | H30: =IF(C30="X",1)+IF(D30="X",2)+IF(E30="X",3)+IF(F30="X",4)+IF(G30="X",5) -> 3
A31: T4_PC2 | B31: Hai avuto la percezione di star migliorando eseguendo il quiz? | G31: x | H31: =IF(C31="X",1)+IF(D31="X",2)+IF(E31="X",3)+IF(F31="X",4)+IF(G31="X",5) -> 5
B32: Motivation
A33: T4_MOT1 | B33: La barra di progresso del quiz ti ha motivato a completare tutte le domande? | F33: x | H33: =IF(C33="X",1)+IF(D33="X",2)+IF(E33="X",3)+IF(F33="X",4)+IF(G33="X",5) -> 4
A34: T4_MOT2 | B34: I feedback ottenuti al controllo di ogni risposta ti hanno motivato nel continuare il quiz? | G34: x | H34: =IF(C34="X",1)+IF(D34="X",2)+IF(E34="X",3)+IF(F34="X",4)+IF(G34="X",5) -> 5
A35: T4_MOT3 | B35: I feedback al termine del quiz, ti hanno motivato a iniziare un nuovo quiz? | D35: x | H35: =IF(C35="X",1)+IF(D35="X",2)+IF(E35="X",3)+IF(F35="X",4)+IF(G35="X",5) -> 2
B37: Knowledge&Skills
A38: T5_KS1 | B38: Sai come etichettare o rinominare le conversazioni salvate per ritrovarle più facilmente? | E38: x | H38: =IF(C38="X",1)+IF(D38="X",2)+IF(E38="X",3)+IF(F38="X",4)+IF(G38="X",5) -> 3
A39: T5_KS2 | B39: Comprendi il significato delle icone per il salvataggio e la condivisione di una conversazione? | G39: x | H39: =IF(C39="X",1)+IF(D39="X",2)+IF(E39="X",3)+IF(F39="X",4)+IF(G39="X",5) -> 5
B40: Personal Control
A41: T5_PC1 | B41: Ti senti libero di eliminare una conversazione salvata tramite il menu contestuale? | D41: x | H41: =IF(C41="X",1)+IF(D41="X",2)+IF(E41="X",3)+IF(F41="X",4)+IF(G41="X",5) -> 2
A42: T5_PC2 | B42: Ti senti in grado di scegliere quali conversazioni siano utili da salvare o condividere? | D42: x | H42: =IF(C42="X",1)+IF(D42="X",2)+IF(E42="X",3)+IF(F42="X",4)+IF(G42="X",5) -> 2
A43: T5_PC3 | B43: Il salvataggio di una conversazione ti è sembrato evidente? | G43: x | H43: =IF(C43="X",1)+IF(D43="X",2)+IF(E43="X",3)+IF(F43="X",4)+IF(G43="X",5) -> 5
B45: Self Efficacy
...

Sheet Utente6
B1: Self Efficacy | C1: Scarso | D1: Sufficiente | E1: Buono | F1: Molto Buono | G1: Eccellente | H1: Valore
A2: T1_SE1 | B2: Ti sei sentito più sicuro nel scegliere un periodo storico usando le anteprime con immagine? | G2: x | H2: =IF(C2="X",1)+IF(D2="X",2)+IF(E2="X",3)+IF(F2="X",4)+IF(G2="X",5) -> 5
A3: T1_SE2 | B3: L'icona o la miniatura del periodo storico ti ha aiutato a selezionarlo con facilità? | E3: x | H3: =IF(C3="X",1)+IF(D3="X",2)+IF(E3="X",3)+IF(F3="X",4)+IF(G3="X",5) -> 3
B4: Knowledge&Skills
A5: T1_KS1 | B5: Sei riuscito a distinguere rapidamente i periodi storici grazie alle immagini e alle etichette? | F5: x | H5: =IF(C5="X",1)+IF(D5="X",2)+IF(E5="X",3)+IF(F5="X",4)+IF(G5="X",5) -> 4
B7: Self Efficacy
A8: T2_SE1 | B8: Quanto la biografia ti ha permesso di scegliere di avviare la conversazione? | G8: x | H8: =IF(C8="X",1)+IF(D8="X",2)+IF(E8="X",3)+IF(F8="X",4)+IF(G8="X",5) -> 5
A9: T2_SE2 | B9: Ti sei sentito sicuro nel cliccare sul pulsante 'Avvia conversazione' per parlare con il personaggio? | G9: x | H9: =IF(C9="X",1)+IF(D9="X",2)+IF(E9="X",3)+IF(F9="X",4)+IF(G9="X",5) -> 5
B10: Knowledge&Skills
A11: T2_KS1 | B11: Sai come avviare una conversazione? | G11: x | H11: =IF(C11="X",1)+IF(D11="X",2)+IF(E11="X",3)+IF(F11="X",4)+IF(G11="X",5) -> 5
B12: Motivation
A13: T2_MOT1 | B13: Quanto ti ha motivato la lettura della biografia del personaggio? | F13: x | H13: =IF(C13="X",1)+IF(D13="X",2)+IF(E13="X",3)+IF(F13="X",4)+IF(G13="X",5) -> 4
A14: T2_MOT2 | B14: L'immagine del personaggio ti ha motivato nell'avviare la conversazione? | F14: x | H14: =IF(C14="X",1)+IF(D14="X",2)+IF(E14="X",3)+IF(F14="X",4)+IF(G14="X",5) -> 4
B16: Self Efficacy
A17: T3_SE1 | B17: Durante la conversazione, ti sei sentito sicuro nell'inviare messaggi usando il campo di testo? | G17: x | H17: =IF(C17="X",1)+IF(D17="X",2)+IF(E17="X",3)+IF(F17="X",4)+IF(G17="X",5) -> 5
A18: T3_SE2 | B18: Durante la conversazione, ti sei sentito sicuro nell'inviare messaggi usando la registrazione vocale? | G18: x | H18: =IF(C18="X",1)+IF(D18="X",2)+IF(E18="X",3)+IF(F18="X",4)+IF(G18="X",5) -> 5
A19: T3_SE3 | B19: Ti è stato facile capire quale pulsante premere per far parlare di nuovo il personaggio? | E19: x | H19: =IF(C19="X",1)+IF(D19="X",2)+IF(E19="X",3)+IF(F19="X",4)+IF(G19="X",5) -> 3
A20: T3_SE4 | B20: Il pulsante 'microfono' era chiaro? | H20: =IF(C20="X",1)+IF(D20="X",2)+IF(E20="X",3)+IF(F20="X",4)+IF(G20="X",5) -> 0
B21: Knowledge&Skills
A22: T3_KS1 | B22: Quanto sei in grado di passare dalla tastiera alla dettatura vocale quando conversi con il personaggio? | G22: x | H22: =IF(C22="X",1)+IF(D22="X",2)+IF(E22="X",3)+IF(F22="X",4)+IF(G22="X",5) -> 5
B23: Motivation
A24: T3_MOT1 | B24: I feedback del personaggio (es. emoji, suoni) ti hanno motivato a continuare la conversazione? | D24: x | H24: =IF(C24="X",1)+IF(D24="X",2)+IF(E24="X",3)+IF(F24="X",4)+IF(G24="X",5) -> 2
B26: Knowledge&Skills
A27: T4_KS1 | B27: Sai come usare il pulsante per la prossima domanda, per navigare nel quiz? | F27: x | H27: =IF(C27="X",1)+IF(D27="X",2)+IF(E27="X",3)+IF(F27="X",4)+IF(G27="X",5) -> 4
A28: T4_KS2 | B28: Sai quante domande restanti ci sono, mentre esegui un quiz? | G28: x | H28: =IF(C28="X",1)+IF(D28="X",2)+IF(E28="X",3)+IF(F28="X",4)+IF(G28="X",5) -> 5
B29: Personal Control
A30: T4_PC1 | B30: Hai avuto la percezione di poter uscire dal quiz se necessario usando l'icona appropriata? | E30: x | H30: =IF(C30="X",1)+IF(D30="X",2)+IF(E30="X",3)+IF(F30="X",4)+IF(G30="X",5) -> 3
A31: T4_PC2 | B31: Hai avuto la percezione di star migliorando eseguendo il quiz? | G31: x | H31: =IF(C31="X",1)+IF(D31="X",2)+IF(E31="X",3)+IF(F31="X",4)+IF(G31="X",5) -> 5
B32: Motivation
A33: T4_MOT1 | B33: La barra di progresso del quiz ti ha motivato a completare tutte le domande? | G33: x | H33: =IF(C33="X",1)+IF(D33="X",2)+IF(E33="X",3)+IF(F33="X",4)+IF(G33="X",5) -> 5
A34: T4_MOT2 | B34: I feedback ottenuti al controllo di ogni risposta ti hanno motivato nel continuare il quiz? | G34: x | H34: =IF(C34="X",1)+IF(D34="X",2)+IF(E34="X",3)+IF(F34="X",4)+IF(G34="X",5) -> 5
A35: T4_MOT3 | B35: I feedback al termine del quiz, ti hanno motivato a iniziare un nuovo quiz? | G35: x | H35: =IF(C35="X",1)+IF(D35="X",2)+IF(E35="X",3)+IF(F35="X",4)+IF(G35="X",5) -> 5
B37: Knowledge&Skills
A38: T5_KS1 | B38: Sai come etichettare o rinominare le conversazioni salvate per ritrovarle più facilmente? | G38: x | H38: =IF(C38="X",1)+IF(D38="X",2)+IF(E38="X",3)+IF(F38="X",4)+IF(G38="X",5) -> 5
A39: T5_KS2 | B39: Comprendi il significato delle icone per il salvataggio e la condivisione di una conversazione? | F39: x | H39: =IF(C39="X",1)+IF(D39="X",2)+IF(E39="X",3)+IF(F39="X",4)+IF(G39="X",5) -> 4
B40: Personal Control
A41: T5_PC1 | B41: Ti senti libero di eliminare una conversazione salvata tramite il menu contestuale? | F41: x | H41: =IF(C41="X",1)+IF(D41="X",2)+IF(E41="X",3)+IF(F41="X",4)+IF(G41="X",5) -> 4
A42: T5_PC2 | B42: Ti senti in grado di scegliere quali conversazioni siano utili da salvare o condividere? | F42: x | H42: =IF(C42="X",1)+IF(D42="X",2)+IF(E42="X",3)+IF(F42="X",4)+IF(G42="X",5) -> 4
A43: T5_PC3 | B43: Il salvataggio di una conversazione ti è sembrato evidente? | G43: x | H43: =IF(C43="X",1)+IF(D43="X",2)+IF(E43="X",3)+IF(F43="X",4)+IF(G43="X",5) -> 5
B45: Self Efficacy
...

Sheet Utente7
B1: Knowledge&Skills | C1: Scarso | D1: Sufficiente | E1: Buono | F1: Molto Buono | G1: Eccellente | H1: Valore
A2: T5_KS1 | B2: Hai ritrovato facilmente la sezione per controllare le conversazioni di una classe? | G2: x | H2: =IF(C2="X",1)+IF(D2="X",2)+IF(E2="X",3)+IF(F2="X",4)+IF(G2="X",5) -> 5
A3: T5_KS2 | B3: La possibilità di selezionare tra le diverse classi, ti ha velocizzato la revisione di una conversazione? | F3: x | H3: =IF(C3="X",1)+IF(D3="X",2)+IF(E3="X",3)+IF(F3="X",4)+IF(G3="X",5) -> 4
B4: Personal Control
A5: T5_PC1 | B5: Sei stato in grado di capire quale studente ha condiviso una conversazione? | E5: x | H5: =IF(C5="X",1)+IF(D5="X",2)+IF(E5="X",3)+IF(F5="X",4)+IF(G5="X",5) -> 3
B7: Self Efficacy
A8: T8_SE1 | B8: Quanto ti è sembrato facile visualizzare una nuova domanda? | F8: x | H8: =IF(C8="X",1)+IF(D8="X",2)+IF(E8="X",3)+IF(F8="X",4)+IF(G8="X",5) -> 4
A9: T8_SE2 | B9: Scegliere prima una classe e poi assegnare una domanda ti è sembrato efficace? | G9: x | H9: =IF(C9="X",1)+IF(D9="X",2)+IF(E9="X",3)+IF(F9="X",4)+IF(G9="X",5) -> 5
B10: Knowledge&Skills
A11: T8_KS1 | B11: Sai come filtrare efficacemente le domande? | E11: x | H11: =IF(C11="X",1)+IF(D11="X",2)+IF(E11="X",3)+IF(F11="X",4)+IF(G11="X",5) -> 3
B12: Personal Control
A13: T8_PC1 | B13: Quanto ti è sembrato facile poter annullare la creazione di una domanda, o eliminarla? | F13: x | H13: =IF(C13="X",1)+IF(D13="X",2)+IF(E13="X",3)+IF(F13="X",4)+IF(G13="X",5) -> 4
B14: Motivation
A15: T8_MOT1 | B15: La possibilità di poter cercare e filtrare le diverse domande per periodo storico, ti motiva ad assegnarne delle nuove? | F15: x | H15: =IF(C15="X",1)+IF(D15="X",2)+IF(E15="X",3)+IF(F15="X",4)+IF(G15="X",5) -> 4
B17: Self Efficacy
A18: T9_SE1 | B18: Ti senti sicuro nel gestire in autonomia la creazione di una classe? | F18: x | H18: =IF(C18="X",1)+IF(D18="X",2)+IF(E18="X",3)+IF(F18="X",4)+IF(G18="X",5) -> 4
A19: T9_SE2 | B19: Quanto sono chiare le informazioni negessarie per la creazione di una classe? | G19: x | H19: =IF(C19="X",1)+IF(D19="X",2)+IF(E19="X",3)+IF(F19="X",4)+IF(G19="X",5) -> 5
B20: Knowledge&Skills
A21: T9_KS1 | B21: Quando organizzi una classe, trovi facilmente le indicazioni richieste? | G21: x | H21: =IF(C21="X",1)+IF(D21="X",2)+IF(E21="X",3)+IF(F21="X",4)+IF(G21="X",5) -> 5
A22: T9_KS2 | B22: Ti è facile visualizzare le informazioni sui partecipanti ad una classe? | G22: x | H22: =IF(C22="X",1)+IF(D22="X",2)+IF(E22="X",3)+IF(F22="X",4)+IF(G22="X",5) -> 5
B23: Personal Control
A24: T9_PC1 | B24: Hai la percezione di poter creare e gestire una classe in autonomia? | F24: x | H24: =IF(C24="X",1)+IF(D24="X",2)+IF(E24="X",3)+IF(F24="X",4)+IF(G24="X",5) -> 4
A25: T9_PC2 | B25: Riesci a gestire liberamente le varie classi che hai creato? | F25: x | H25: =IF(C25="X",1)+IF(D25="X",2)+IF(E25="X",3)+IF(F25="X",4)+IF(G25="X",5) -> 4
A26: T9_PC3 | B26: Riesci a gestire liberamente gli studenti di una classe? | E26: x | H26: =IF(C26="X",1)+IF(D26="X",2)+IF(E26="X",3)+IF(F26="X",4)+IF(G26="X",5) -> 3
B27: Motivation
A28: T9_MOT1 | B28: Avere il pieno controllo sull’organizzazione delle attività didattiche ti fa sentire più motivato e sereno nel tuo lavoro? | G28: x | H28: =IF(C28="X",1)+IF(D28="X",2)+IF(E28="X",3)+IF(F28="X",4)+IF(G28="X",5) -> 5
B30: Self Efficacy
A31: T10_SE1 | B31: Ti senti sicuro nell’assegnare domande alla classe ? | G31: x | H31: =IF(C31="X",1)+IF(D31="X",2)+IF(E31="X",3)+IF(F31="X",4)+IF(G31="X",5) -> 5
A32: T10_SE2 | B32: Quando decidi di proporre una nuova domanda, le informazioni da inserire ti sono chiare? | F32: x | H32: =IF(C32="X",1)+IF(D32="X",2)+IF(E32="X",3)+IF(F32="X",4)+IF(G32="X",5) -> 4
A33: T10_SE3 | B33: Ti è facile scegliere una classe a cui assegnare una domanda? | F33: x | H33: =IF(C33="X",1)+IF(D33="X",2)+IF(E33="X",3)+IF(F33="X",4)+IF(G33="X",5) -> 4
B34: Knowledge&Skills
A35: T10_KS1 | B35: Ti è facile scegliere il periodo storico di riferimento di una domanda? | G35: x | H35: =IF(C35="X",1)+IF(D35="X",2)+IF(E35="X",3)+IF(F35="X",4)+IF(G35="X",5) -> 5
B36: Personal Control
A37: T10_PC1 | B37: Ti senti libero di scegliere quali domande proporre alla classe e in quali momenti farlo? | F37: x | H37: =IF(C37="X",1)+IF(D37="X",2)+IF(E37="X",3)+IF(F37="X",4)+IF(G37="X",5) -> 4
A38: T10_PC2 | B38: Quanto è semplice per te modificare o adattare una domanda già proposta, se le esigenze della classe cambiano? | F38: x | H38: =IF(C38="X",1)+IF(D38="X",2)+IF(E38="X",3)+IF(F38="X",4)+IF(G38="X",5) -> 4
B39: Motivation
A40: T10_MOT1 | B40: Proporre domande agli studenti, ti aiuta a rendere le lezioni più stimolanti e partecipate? | G40: x | H40: =IF(C40="X",1)+IF(D40="X",2)+IF(E40="X",3)+IF(F40="X",4)+IF(G40="X",5) -> 5
A41: T10_MOT2 | B41: Quanto è importante per te poter adattare le domande o le attività ai diversi bisogni dei tuoi studenti? | G41: x | H41: =IF(C41="X",1)+IF(D41="X",2)+IF(E41="X",3)+IF(F41="X",4)+IF(G41="X",5) -> 5

Sheet Utente8
B1: Knowledge&Skills | C1: Scarso | D1: Sufficiente | E1: Buono | F1: Molto Buono | G1: Eccellente | H1: Valore
A2: T5_KS1 | B2: Hai ritrovato facilmente la sezione per controllare le conversazioni di una classe? | F2: x | H2: =IF(C2="X",1)+IF(D2="X",2)+IF(E2="X",3)+IF(F2="X",4)+IF(G2="X",5) -> 4
A3: T5_KS2 | B3: La possibilità d iselezionare tra le diverse classi, ti ha velocizzato la revisione di una conversazione? | G3: x | H3: =IF(C3="X",1)+IF(D3="X",2)+IF(E3="X",3)+IF(F3="X",4)+IF(G3="X",5) -> 5
B4: Personal Control
A5: T5_PC1 | B5: Sei stato in grado di capire quale studente ha condiviso una conversazione? | F5: x | H5: =IF(C5="X",1)+IF(D5="X",2)+IF(E5="X",3)+IF(F5="X",4)+IF(G5="X",5) -> 4
B7: Self Efficacy
A8: T8_SE1 | B8: Quanto ti è sembrato facile visualizzare una nuova domanda? | F8: x | H8: =IF(C8="X",1)+IF(D8="X",2)+IF(E8="X",3)+IF(F8="X",4)+IF(G8="X",5) -> 4
A9: T8_SE2 | B9: Scegliere prima una classe e poi assegnare una domanda ti è sembrato efficace? | F9: x | H9: =IF(C9="X",1)+IF(D9="X",2)+IF(E9="X",3)+IF(F9="X",4)+IF(G9="X",5) -> 4
B10: Knowledge&Skills
A11: T8_KS1 | B11: Sai come filtrare efficacemente le domande? | E11: x | H11: =IF(C11="X",1)+IF(D11="X",2)+IF(E11="X",3)+IF(F11="X",4)+IF(G11="X",5) -> 3
B12: Personal Control
A13: T8_PC1 | B13: Quanto ti è sembrato facile poter annullare la creazione di una domanda, o eliminarla? | F13: x | H13: =IF(C13="X",1)+IF(D13="X",2)+IF(E13="X",3)+IF(F13="X",4)+IF(G13="X",5) -> 4
B14: Motivation
A15: T8_MOT1 | B15: La possibilità di poter cercare e filtrare le diverse domande per periodo storico, ti motiva ad assegnarne delle nuove? | E15: x | H15: =IF(C15="X",1)+IF(D15="X",2)+IF(E15="X",3)+IF(F15="X",4)+IF(G15="X",5) -> 3
B17: Self Efficacy
A18: T9_SE1 | B18: Ti senti sicuro nel gestire in autonomia la creazione di una classe? | F18: x | H18: =IF(C18="X",1)+IF(D18="X",2)+IF(E18="X",3)+IF(F18="X",4)+IF(G18="X",5) -> 4
A19: T9_SE2 | B19: Quanto sono chiare le informazioni negessarie per la creazione di una classe? | G19: x | H19: =IF(C19="X",1)+IF(D19="X",2)+IF(E19="X",3)+IF(F19="X",4)+IF(G19="X",5) -> 5
B20: Knowledge&Skills
A21: T9_KS1 | B21: Quando organizzi una classe, trovi facilmente le indicazioni richieste? | F21: x | H21: =IF(C21="X",1)+IF(D21="X",2)+IF(E21="X",3)+IF(F21="X",4)+IF(G21="X",5) -> 4
A22: T9_KS2 | B22: Ti è facile visualizzare le informazioni sui partecipanti ad una classe? | G22: x | H22: =IF(C22="X",1)+IF(D22="X",2)+IF(E22="X",3)+IF(F22="X",4)+IF(G22="X",5) -> 5
B23: Personal Control
A24: T9_PC1 | B24: Hai la percezione di poter creare e gestire una classe in autonomia? | F24: x | H24: =IF(C24="X",1)+IF(D24="X",2)+IF(E24="X",3)+IF(F24="X",4)+IF(G24="X",5) -> 4
A25: T9_PC2 | B25: Riesci a gestire liberamente le varie classi che hai creato? | E25: x | H25: =IF(C25="X",1)+IF(D25="X",2)+IF(E25="X",3)+IF(F25="X",4)+IF(G25="X",5) -> 3
A26: T9_PC3 | B26: Riesci a gestire liberamente gli studenti di una classe? | F26: x | H26: =IF(C26="X",1)+IF(D26="X",2)+IF(E26="X",3)+IF(F26="X",4)+IF(G26="X",5) -> 4
B27: Motivation
A28: T9_MOT1 | B28: Avere il pieno controllo sull’organizzazione delle attività didattiche ti fa sentire più motivato e sereno nel tuo lavoro? | F28: x | H28: =IF(C28="X",1)+IF(D28="X",2)+IF(E28="X",3)+IF(F28="X",4)+IF(G28="X",5) -> 4
B30: Self Efficacy
A31: T10_SE1 | B31: Ti senti sicuro nell’assegnare domande alla classe ? | F31: x | H31: =IF(C31="X",1)+IF(D31="X",2)+IF(E31="X",3)+IF(F31="X",4)+IF(G31="X",5) -> 4
A32: T10_SE2 | B32: Quando decidi di proporre una nuova domanda, le informazioni da inserire ti sono chiare? | G32: x | H32: =IF(C32="X",1)+IF(D32="X",2)+IF(E32="X",3)+IF(F32="X",4)+IF(G32="X",5) -> 5
A33: T10_SE3 | B33: Ti è facile scegliere una classe a cui assegnare una domanda? | G33: x | H33: =IF(C33="X",1)+IF(D33="X",2)+IF(E33="X",3)+IF(F33="X",4)+IF(G33="X",5) -> 5
B34: Knowledge&Skills
A35: T10_KS1 | B35: Ti è facile scegliere il periodo storico di riferimento di una domanda? | G35: x | H35: =IF(C35="X",1)+IF(D35="X",2)+IF(E35="X",3)+IF(F35="X",4)+IF(G35="X",5) -> 5
B36: Personal Control
A37: T10_PC1 | B37: Ti senti libero di scegliere quali domande proporre alla classe e in quali momenti farlo? | F37: x | H37: =IF(C37="X",1)+IF(D37="X",2)+IF(E37="X",3)+IF(F37="X",4)+IF(G37="X",5) -> 4
A38: T10_PC2 | B38: Quanto è semplice per te modificare o adattare una domanda già proposta, se le esigenze della classe cambiano? | F38: x | H38: =IF(C38="X",1)+IF(D38="X",2)+IF(E38="X",3)+IF(F38="X",4)+IF(G38="X",5) -> 4
B39: Motivation
A40: T10_MOT1 | B40: Proporre domande agli studenti, ti aiuta a rendere le lezioni più stimolanti e partecipate? | G40: x | H40: =IF(C40="X",1)+IF(D40="X",2)+IF(E40="X",3)+IF(F40="X",4)+IF(G40="X",5) -> 5
A41: T10_MOT2 | B41: Quanto è importante per te poter adattare le domande o le attività ai diversi bisogni dei tuoi studenti? | G41: x | H41: =IF(C41="X",1)+IF(D41="X",2)+IF(E41="X",3)+IF(F41="X",4)+IF(G41="X",5) -> 5

Sheet Utente9
B1: Knowledge&Skills | C1: Scarso | D1: Sufficiente | E1: Buono | F1: Molto Buono | G1: Eccellente | H1: Valore
A2: T5_KS1 | B2: Hai ritrovato facilmente la sezione per controllare le conversazioni di una classe? | F2: x | H2: =IF(C2="X",1)+IF(D2="X",2)+IF(E2="X",3)+IF(F2="X",4)+IF(G2="X",5) -> 4
A3: T5_KS2 | B3: La possibilità d iselezionare tra le diverse classi, ti ha velocizzato la revisione di una conversazione? | F3: x | H3: =IF(C3="X",1)+IF(D3="X",2)+IF(E3="X",3)+IF(F3="X",4)+IF(G3="X",5) -> 4
B4: Personal Control
A5: T5_PC1 | B5: Sei stato in grado di capire quale studente ha condiviso una conversazione? | E5: x | H5: =IF(C5="X",1)+IF(D5="X",2)+IF(E5="X",3)+IF(F5="X",4)+IF(G5="X",5) -> 3
B7: Self Efficacy
A8: T8_SE1 | B8: Quanto ti è sembrato facile visualizzare una nuova domanda? | F8: x | H8: =IF(C8="X",1)+IF(D8="X",2)+IF(E8="X",3)+IF(F8="X",4)+IF(G8="X",5) -> 4
A9: T8_SE2 | B9: Scegliere prima una classe e poi assegnare una domanda ti è sembrato efficace? | F9: x | H9: =IF(C9="X",1)+IF(D9="X",2)+IF(E9="X",3)+IF(F9="X",4)+IF(G9="X",5) -> 4
B10: Knowledge&Skills
A11: T8_KS1 | B11: Sai come filtrare efficacemente le domande? | F11: x | H11: =IF(C11="X",1)+IF(D11="X",2)+IF(E11="X",3)+IF(F11="X",4)+IF(G11="X",5) -> 4
B12: Personal Control
A13: T8_PC1 | B13: Quanto ti è sembrato facile poter annullare la creazione di una domanda, o eliminarla? | E13: x | H13: =IF(C13="X",1)+IF(D13="X",2)+IF(E13="X",3)+IF(F13="X",4)+IF(G13="X",5) -> 3
B14: Motivation
A15: T8_MOT1 | B15: La possibilità di poter cercare e filtrare le diverse domande per periodo storico, ti motiva ad assegnarne delle nuove? | F15: x | H15: =IF(C15="X",1)+IF(D15="X",2)+IF(E15="X",3)+IF(F15="X",4)+IF(G15="X",5) -> 4
B17: Self Efficacy
A18: T9_SE1 | B18: Ti senti sicuro nel gestire in autonomia la creazione di una classe? | F18: x | H18: =IF(C18="X",1)+IF(D18="X",2)+IF(E18="X",3)+IF(F18="X",4)+IF(G18="X",5) -> 4
A19: T9_SE2 | B19: Quanto sono chiare le informazioni negessarie per la creazione di una classe? | F19: x | H19: =IF(C19="X",1)+IF(D19="X",2)+IF(E19="X",3)+IF(F19="X",4)+IF(G19="X",5) -> 4
B20: Knowledge&Skills
A21: T9_KS1 | B21: Quando organizzi una classe, trovi facilmente le indicazioni richieste? | G21: x | H21: =IF(C21="X",1)+IF(D21="X",2)+IF(E21="X",3)+IF(F21="X",4)+IF(G21="X",5) -> 5
A22: T9_KS2 | B22: Ti è facile visualizzare le informazioni sui partecipanti ad una classe? | G22: x | H22: =IF(C22="X",1)+IF(D22="X",2)+IF(E22="X",3)+IF(F22="X",4)+IF(G22="X",5) -> 5
B23: Personal Control
A24: T9_PC1 | B24: Hai la percezione di poter creare e gestire una classe in autonomia? | F24: x | H24: =IF(C24="X",1)+IF(D24="X",2)+IF(E24="X",3)+IF(F24="X",4)+IF(G24="X",5) -> 4
A25: T9_PC2 | B25: Riesci a gestire liberamente le varie classi che hai creato? | F25: x | H25: =IF(C25="X",1)+IF(D25="X",2)+IF(E25="X",3)+IF(F25="X",4)+IF(G25="X",5) -> 4
A26: T9_PC3 | B26: Riesci a gestire liberamente gli studenti di una classe? | E26: x | H26: =IF(C26="X",1)+IF(D26="X",2)+IF(E26="X",3)+IF(F26="X",4)+IF(G26="X",5) -> 3
B27: Motivation
A28: T9_MOT1 | B28: Avere il pieno controllo sull’organizzazione delle attività didattiche ti fa sentire più motivato e sereno nel tuo lavoro? | G28: x | H28: =IF(C28="X",1)+IF(D28="X",2)+IF(E28="X",3)+IF(F28="X",4)+IF(G28="X",5) -> 5
B30: Self Efficacy
A31: T10_SE1 | B31: Ti senti sicuro nell’assegnare domande alla classe ? | G31: x | H31: =IF(C31="X",1)+IF(D31="X",2)+IF(E31="X",3)+IF(F31="X",4)+IF(G31="X",5) -> 5
A32: T10_SE2 | B32: Quando decidi di proporre una nuova domanda, le informazioni da inserire ti sono chiare? | F32: x | H32: =IF(C32="X",1)+IF(D32="X",2)+IF(E32="X",3)+IF(F32="X",4)+IF(G32="X",5) -> 4
A33: T10_SE3 | B33: Ti è facile scegliere una classe a cui assegnare una domanda? | F33: x | H33: =IF(C33="X",1)+IF(D33="X",2)+IF(E33="X",3)+IF(F33="X",4)+IF(G33="X",5) -> 4
B34: Knowledge&Skills
A35: T10_KS1 | B35: Ti è facile scegliere il periodo storico di riferimento di una domanda? | F35: x | H35: =IF(C35="X",1)+IF(D35="X",2)+IF(E35="X",3)+IF(F35="X",4)+IF(G35="X",5) -> 4
B36: Personal Control
A37: T10_PC1 | B37: Ti senti libero di scegliere quali domande proporre alla classe e in quali momenti farlo? | F37: x | H37: =IF(C37="X",1)+IF(D37="X",2)+IF(E37="X",3)+IF(F37="X",4)+IF(G37="X",5) -> 4
A38: T10_PC2 | B38: Quanto è semplice per te modificare o adattare una domanda già proposta, se le esigenze della classe cambiano? | F38: x | H38: =IF(C38="X",1)+IF(D38="X",2)+IF(E38="X",3)+IF(F38="X",4)+IF(G38="X",5) -> 4
B39: Motivation
A40: T10_MOT1 | B40: Proporre domande agli studenti, ti aiuta a rendere le lezioni più stimolanti e partecipate? | E40: x | H40: =IF(C40="X",1)+IF(D40="X",2)+IF(E40="X",3)+IF(F40="X",4)+IF(G40="X",5) -> 3
A41: T10_MOT2 | B41: Quanto è importante per te poter adattare le domande o le attività ai diversi bisogni dei tuoi studenti? | G41: x | H41: =IF(C41="X",1)+IF(D41="X",2)+IF(E41="X",3)+IF(F41="X",4)+IF(G41="X",5) -> 5

Sheet Utente10
B1: Knowledge&Skills | C1: Scarso | D1: Sufficiente | E1: Buono | F1: Molto Buono | G1: Eccellente | H1: Valore
A2: T5_KS1 | B2: Hai ritrovato facilmente la sezione per controllare le conversazioni di una classe? | F2: x | H2: =IF(C2="X",1)+IF(D2="X",2)+IF(E2="X",3)+IF(F2="X",4)+IF(G2="X",5) -> 4
A3: T5_KS2 | B3: La possibilità d iselezionare tra le diverse classi, ti ha velocizzato la revisione di una conversazione? | D3: x | H3: =IF(C3="X",1)+IF(D3="X",2)+IF(E3="X",3)+IF(F3="X",4)+IF(G3="X",5) -> 2
B4: Personal Control
A5: T5_PC1 | B5: Sei stato in grado di capire quale studente ha condiviso una conversazione? | F5: x | H5: =IF(C5="X",1)+IF(D5="X",2)+IF(E5="X",3)+IF(F5="X",4)+IF(G5="X",5) -> 4
B7: Self Efficacy
A8: T8_SE1 | B8: Quanto ti è sembrato facile visualizzare una nuova domanda? | F8: x | H8: =IF(C8="X",1)+IF(D8="X",2)+IF(E8="X",3)+IF(F8="X",4)+IF(G8="X",5) -> 4
A9: T8_SE2 | B9: Scegliere prima una classe e poi assegnare una domanda ti è sembrato efficace? | G9: x | H9: =IF(C9="X",1)+IF(D9="X",2)+IF(E9="X",3)+IF(F9="X",4)+IF(G9="X",5) -> 5
B10: Knowledge&Skills
A11: T8_KS1 | B11: Sai come filtrare efficacemente le domande? | G11: x | H11: =IF(C11="X",1)+IF(D11="X",2)+IF(E11="X",3)+IF(F11="X",4)+IF(G11="X",5) -> 5
B12: Personal Control
A13: T8_PC1 | B13: Quanto ti è sembrato facile poter annullare la creazione di una domanda, o eliminarla? | F13: x | H13: =IF(C13="X",1)+IF(D13="X",2)+IF(E13="X",3)+IF(F13="X",4)+IF(G13="X",5) -> 4
B14: Motivation
A15: T8_MOT1 | B15: La possibilità di poter cercare e filtrare le diverse domande per periodo storico, ti motiva ad assegnarne delle nuove? | G15: x | H15: =IF(C15="X",1)+IF(D15="X",2)+IF(E15="X",3)+IF(F15="X",4)+IF(G15="X",5) -> 5
B17: Self Efficacy
A18: T9_SE1 | B18: Ti senti sicuro nel gestire in autonomia la creazione di una classe? | F18: x | H18: =IF(C18="X",1)+IF(D18="X",2)+IF(E18="X",3)+IF(F18="X",4)+IF(G18="X",5) -> 4
A19: T9_SE2 | B19: Quanto sono chiare le informazioni negessarie per la creazione di una classe? | G19: x | H19: =IF(C19="X",1)+IF(D19="X",2)+IF(E19="X",3)+IF(F19="X",4)+IF(G19="X",5) -> 5
B20: Knowledge&Skills
A21: T9_KS1 | B21: Quando organizzi una classe, trovi facilmente le indicazioni richieste? | G21: x | H21: =IF(C21="X",1)+IF(D21="X",2)+IF(E21="X",3)+IF(F21="X",4)+IF(G21="X",5) -> 5
A22: T9_KS2 | B22: Ti è facile visualizzare le informazioni sui partecipanti ad una classe? | G22: x | H22: =IF(C22="X",1)+IF(D22="X",2)+IF(E22="X",3)+IF(F22="X",4)+IF(G22="X",5) -> 5
B23: Personal Control
A24: T9_PC1 | B24: Hai la percezione di poter creare e gestire una classe in autonomia? | F24: x | H24: =IF(C24="X",1)+IF(D24="X",2)+IF(E24="X",3)+IF(F24="X",4)+IF(G24="X",5) -> 4
A25: T9_PC2 | B25: Riesci a gestire liberamente le varie classi che hai creato? | F25: x | H25: =IF(C25="X",1)+IF(D25="X",2)+IF(E25="X",3)+IF(F25="X",4)+IF(G25="X",5) -> 4
A26: T9_PC3 | B26: Riesci a gestire liberamente gli studenti di una classe? | E26: x | H26: =IF(C26="X",1)+IF(D26="X",2)+IF(E26="X",3)+IF(F26="X",4)+IF(G26="X",5) -> 3
B27: Motivation
A28: T9_MOT1 | B28: Avere il pieno controllo sull’organizzazione delle attività didattiche ti fa sentire più motivato e sereno nel tuo lavoro? | F28: x | H28: =IF(C28="X",1)+IF(D28="X",2)+IF(E28="X",3)+IF(F28="X",4)+IF(G28="X",5) -> 4
B30: Self Efficacy
A31: T10_SE1 | B31: Ti senti sicuro nell’assegnare domande alla classe ? | E31: x | H31: =IF(C31="X",1)+IF(D31="X",2)+IF(E31="X",3)+IF(F31="X",4)+IF(G31="X",5) -> 3
A32: T10_SE2 | B32: Quando decidi di proporre una nuova domanda, le informazioni da inserire ti sono chiare? | G32: x | H32: =IF(C32="X",1)+IF(D32="X",2)+IF(E32="X",3)+IF(F32="X",4)+IF(G32="X",5) -> 5
A33: T10_SE3 | B33: Ti è facile scegliere una classe a cui assegnare una domanda? | E33: x | H33: =IF(C33="X",1)+IF(D33="X",2)+IF(E33="X",3)+IF(F33="X",4)+IF(G33="X",5) -> 3
B34: Knowledge&Skills
A35: T10_KS1 | B35: Ti è facile scegliere il periodo storico di riferimento di una domanda? | G35: x | H35: =IF(C35="X",1)+IF(D35="X",2)+IF(E35="X",3)+IF(F35="X",4)+IF(G35="X",5) -> 5
B36: Personal Control
A37: T10_PC1 | B37: Ti senti libero di scegliere quali domande proporre alla classe e in quali momenti farlo? | F37: x | H37: =IF(C37="X",1)+IF(D37="X",2)+IF(E37="X",3)+IF(F37="X",4)+IF(G37="X",5) -> 4
A38: T10_PC2 | B38: Quanto è semplice per te modificare o adattare una domanda già proposta, se le esigenze della classe cambiano? | E38: x | H38: =IF(C38="X",1)+IF(D38="X",2)+IF(E38="X",3)+IF(F38="X",4)+IF(G38="X",5) -> 3
B39: Motivation
A40: T10_MOT1 | B40: Proporre domande agli studenti, ti aiuta a rendere le lezioni più stimolanti e partecipate? | G40: x | H40: =IF(C40="X",1)+IF(D40="X",2)+IF(E40="X",3)+IF(F40="X",4)+IF(G40="X",5) -> 5
A41: T10_MOT2 | B41: Quanto è importante per te poter adattare le domande o le attività ai diversi bisogni dei tuoi studenti? | G41: x | H41: =IF(C41="X",1)+IF(D41="X",2)+IF(E41="X",3)+IF(F41="X",4)+IF(G41="X",5) -> 5

Sheet MEDIE
C1: Valore
A2: T1_SE1 | B2: Ti sei sentito più sicuro nel scegliere un periodo storico usando le anteprime con immagine? | C2: =AVERAGE(Utente1!H2,Utente2!H2,Utente3!H2,Utente4!H2,Utente5!H2,Utente6!H2) -> 3.8333333 | D2: MEDIA DELLE RISPOSTE
A3: T1_SE2 | B3: L'icona o la miniatura del periodo storico ti ha aiutato a selezionarlo con facilità? | C3: =AVERAGE(Utente1!H3,Utente2!H3,Utente3!H3,Utente4!H3,Utente5!H3,Utente6!H3) -> 3.6666667 | D3: MEDIA DELLE RISPOSTE
C4: =AVERAGE(C2:C3) -> 3.75 | D4: MEDIA TRA I VALORI MEDI RELATIVI A QUELL'ABILITA' | E4: Self Efficacy
A5: T1_KS1 | B5: Sei riuscito a distinguere rapidamente i periodi storici grazie alle immagini e alle etichette? | C5: =AVERAGE(Utente1!H5,Utente2!H5,Utente3!H5,Utente4!H5,Utente5!H5,Utente6!H5) -> 3.6666667 | D5: MEDIA DELLE RISPOSTE
C6: =AVERAGE(C5) -> 3.6666667 | D6: MEDIA TRA I VALORI MEDI RELATIVI A QUELL'ABILITA' | E6: Knowledge&Skills
A7: T2_SE1 | B7: Quanto la biografia ti ha permesso di scegliere di avviare la conversazione? | C7: =AVERAGE(Utente1!H8,Utente2!H8,Utente3!H8,Utente4!H8,Utente5!H8,Utente6!H8) -> 4.6 | D7: MEDIA DELLE RISPOSTE
A8: T2_SE2 | B8: Ti sei sentito sicuro nel cliccare sul pulsante 'Avvia conversazione' per parlare con il personaggio? | C8: =AVERAGE(Utente1!H9,Utente2!H9,Utente3!H9,Utente4!H9,Utente5!H9,Utente6!H9) -> 3.8333333 | D8: MEDIA DELLE RISPOSTE
C9: =AVERAGE(C7:C8) -> 4.2166667 | D9: MEDIA TRA I VALORI MEDI RELATIVI A QUELL'ABILITA' | E9: Self Efficacy
A10: T2_KS1 | B10: Sai come avviare una conversazione? | C10: =AVERAGE(Utente1!H11,Utente2!H11,Utente3!H11,Utente4!H11,Utente5!H11,Utente6!H11) -> 4.6666667 | D10: MEDIA DELLE RISPOSTE
C11: =AVERAGE(C10) -> 4.6666667 | D11: MEDIA TRA I VALORI MEDI RELATIVI A QUELL'ABILITA' | E11: Knowledge&Skills
A12: T2_MOT1 | B12: Quanto ti ha motivato la lettura della biografia del personaggio? | C12: =AVERAGE(Utente1!H13,Utente2!H13,Utente3!H13,Utente4!H13,Utente5!H13,Utente6!H13) -> 4.6666667 | D12: MEDIA DELLE RISPOSTE
A13: T2_MOT2 | B13: L'immagine del personaggio ti ha motivato nell'avviare la conversazione? | C13: =AVERAGE(Utente1!H14,Utente2!H14,Utente3!H14,Utente4!H14,Utente5!H14,Utente6!H14) -> 3.6666667 | D13: MEDIA DELLE RISPOSTE
C14: =AVERAGE(C12:C13) -> 4.1666667 | D14: MEDIA TRA I VALORI MEDI RELATIVI A QUELL'ABILITA' | E14: Motivation
A15: T3_SE1 | B15: Durante la conversazione, ti sei sentito sicuro nell'inviare messaggi usando il campo di testo? | C15: =AVERAGE(Utente1!H17,Utente2!H17,Utente3!H17,Utente4!H17,Utente5!H17,Utente6!H17) -> 4.8 | D15: MEDIA DELLE RISPOSTE
A16: T3_SE2 | B16: Durante la conversazione, ti sei sentito sicuro nell'inviare messaggi usando la registrazione vocale? | C16: =AVERAGE(Utente1!H18,Utente2!H18,Utente3!H18,Utente4!H18,Utente5!H18,Utente6!H18) -> 4.6666667 | D16: MEDIA DELLE RISPOSTE
A17: T3_SE3 | B17: Ti è stato facile capire quale pulsante premere per far parlare di nuovo il personaggio? | C17: =AVERAGE(Utente1!H19,Utente2!H19,Utente3!H19,Utente4!H19,Utente5!H19,Utente6!H19) -> 3.3333333 | D17: MEDIA DELLE RISPOSTE
A18: T3_SE4 | B18: Il pulsante 'microfono' era chiaro? | C18: =AVERAGE(Utente1!H20,Utente2!H20,Utente3!H20,Utente4!H20,Utente5!H20,Utente6!H20) -> 2.4 | D18: MEDIA DELLE RISPOSTE
C19: =AVERAGE((C15:C18)) -> 3.8 | D19: MEDIA TRA I VALORI MEDI RELATIVI A QUELL'ABILITA' | E19: Self Efficacy
A20: T3_KS1 | B20: Quanto sei in grado di passare dalla tastiera alla dettatura vocale quando conversi con il personaggio? | C20: =AVERAGE(Utente1!H22,Utente2!H22,Utente3!H22,Utente4!H22,Utente5!H22,Utente6!H22) -> 3.8333333 | D20: MEDIA DELLE RISPOSTE
C21: =AVERAGE(C20) -> 3.8333333 | D21: MEDIA TRA I VALORI MEDI RELATIVI A QUELL'ABILITA' | E21: Knowledge&Skills
A22: T3_MOT1 | B22: I feedback del personaggio (es. emoji, suoni) ti hanno motivato a continuare la conversazione? | C22: =AVERAGE(Utente1!H24,Utente2!H24,Utente3!H24,Utente4!H24,Utente5!H24,Utente6!H24) -> 3.5 | D22: MEDIA DELLE RISPOSTE
C23: =AVERAGE(C22) -> 3.5 | D23: MEDIA TRA I VALORI MEDI RELATIVI A QUELL'ABILITA' | E23: Motivation
A24: T4_KS1 | B24: Sai come usare il pulsante per la prossima domanda, per navigare nel quiz? | C24: =AVERAGE(Utente1!H27,Utente2!H27,Utente3!H27,Utente4!H27,Utente5!H27,Utente6!H27) -> 4.1666667 | D24: MEDIA DELLE RISPOSTE
A25: T4_KS2 | B25: Sai quante domande restanti ci sono, mentre esegui un quiz? | C25: =AVERAGE(Utente1!H28,Utente2!H28,Utente3!H28,Utente4!H28,Utente5!H28,Utente6!H28) -> 4.8 | D25: MEDIA DELLE RISPOSTE
C26: =AVERAGE(C24:C25) -> 4.4833333 | D26: MEDIA TRA I VALORI MEDI RELATIVI A QUELL'ABILITA' | E26: Knowledge&Skills
A27: T4_PC1 | B27: Hai avuto la percezione di poter uscire dal quiz se necessario usando l'icona appropriata? | C27: =AVERAGE(Utente1!H30,Utente2!H30,Utente3!H30,Utente4!H30,Utente5!H30,Utente6!H30) -> 2.8333333 | D27: MEDIA DELLE RISPOSTE
A28: T4_PC2 | B28: Hai avuto la percezione di star migliorando eseguendo il quiz? | C28: =AVERAGE(Utente1!H31,Utente2!H31,Utente3!H31,Utente4!H31,Utente5!H31,Utente6!H31) -> 4.1666667 | D28: MEDIA DELLE RISPOSTE
C29: =AVERAGE(C27:C28) -> 3.5 | D29: MEDIA TRA I VALORI MEDI RELATIVI A QUELL'ABILITA' | E29: Personal Control
A30: T4_MOT1 | B30: La barra di progresso del quiz ti ha motivato a completare tutte le domande? | C30: =AVERAGE(Utente1!H33,Utente2!H33,Utente3!H33,Utente4!H33,Utente5!H33,Utente6!H33) -> 3.8333333 | D30: MEDIA DELLE RISPOSTE
A31: T4_MOT2 | B31: I feedback ottenuti al controllo di ogni risposta ti hanno motivato nel continuare il quiz? | C31: =AVERAGE(Utente1!H34,Utente2!H34,Utente3!H34,Utente4!H34,Utente5!H34,Utente6!H34) -> 4 | D31: MEDIA DELLE RISPOSTE
A32: T4_MOT3 | B32: I feedback al termine del quiz, ti hanno motivato a iniziare un nuovo quiz? | C32: =AVERAGE(Utente1!H35,Utente2!H35,Utente3!H35,Utente4!H35,Utente5!H35,Utente6!H35) -> 3.6666667 | D32: MEDIA DELLE RISPOSTE
C33: =AVERAGE(C30:C32) -> 3.8333333 | D33: MEDIA TRA I VALORI MEDI RELATIVI A QUELL'ABILITA' | E33: Motivation
A34: T5_KS1 | B34: Sai come etichettare o rinominare le conversazioni salvate per ritrovarle più facilmente? | C34: =AVERAGE(Utente1!H38,Utente2!H38,Utente3!H38,Utente4!H38,Utente5!H38,Utente6!H38) -> 3.8333333 | D34: MEDIA DELLE RISPOSTE
A35: T5_KS2 | B35: Comprendi il significato delle icone per il salvataggio e la condivisione di una conversazione? | C35: =AVERAGE(Utente1!H39,Utente2!H39,Utente3!H39,Utente4!H39,Utente5!H39,Utente6!H39) -> 4.6666667 | D35: MEDIA DELLE RISPOSTE
C36: =AVERAGE(C34:C35) -> 4.25 | D36: MEDIA TRA I VALORI MEDI RELATIVI A QUELL'ABILITA' | E36: Knowledge&Skills
A37: T5_PC1 | B37: Ti senti libero di eliminare una conversazione salvata tramite il menu contestuale? | C37: =AVERAGE(Utente1!H41,Utente2!H41,Utente3!H41,Utente4!H41,Utente5!H41,Utente6!H41) -> 3 | D37: MEDIA DELLE RISPOSTE
A38: T5_PC2 | B38: Ti senti in grado di scegliere quali conversazioni siano utili da salvare o condividere? | C38: =AVERAGE(Utente1!H42,Utente2!H42,Utente3!H42,Utente4!H42,Utente5!H42,Utente6!H42) -> 3.8333333 | D38: MEDIA DELLE RISPOSTE
A39: T5_PC3 | B39: Il salvataggio di una conversazione ti è sembrato evidente? | C39: =AVERAGE(Utente1!H43,Utente2!H43,Utente3!H43,Utente4!H43,Utente5!H43,Utente6!H43) -> 4.1666667 | D39: MEDIA DELLE RISPOSTE
C40: =AVERAGE(C37:C39) -> 3.6666667 | D40: MEDIA TRA I VALORI MEDI RELATIVI A QUELL'ABILITA' | E40: Personal Control
...

Sheet TabRisultati
