Workbook

Sheet BEHAVIOURABILITY
A1: TASK | B1: Decision Making | C1: Self-Management | D1: Communication | E1: Engagement
A2: TASK T1 Selezionare un periodo storico | B2: SE, K&S
A3: TASK T2 Avviare una conversazione | B3: SE, K&S | D3: SE, MOT | E3: MOT
A4: TASK T3 Condurre una conversazione con un personaggio | D4: SE, MOT | E4: MOT, K&S
A5: TASK T4 Partecipare a quiz | B5: K&S | C5: PC, MOT | E5: MOT, K&S
A6: TASK T5 Salvare o rivedere una conversazione utile | C6: PC, K&S
A7: TASK T6 Condividere una conversazione con compagni o insegnanti | D7: SE, MOT
A8: TASK T7 Ricevere feedback e premi virtuali | B8: K&S | C8: PC, MOT | E8: MOT, K&S
A9: TASK T8 Visualizzare le domande assegnate dall'insegnante | B9: SE, K&S | C9: PC, MOT
A10: TASK T9 Creare una classe virtuale | B10: SE, K&S | C10: PC, MOT
A11: TASK T10 Assegnare domande alla classe | B11: SE, K&S | C11: PC
A12: TASK T11 Partecipare ad una classe virtuale | B12: SE, K&S | C12: PC | D12: SE, MOT | E12: MOT, K&S
A13: TASK T12 Seguire lo studio del figlio | B13: PC | C13: PC | E13: MOT
A14: Legenda
A15: SE = Self-Efficacy
A16: K&S = Knowledge & Skills
A17: PC = Personal Control
A18: MOT = Motivation

Sheet Quest.Dustin
B1: Self Efficacy | C1: Scarso | D1: Sufficiente | E1: Buono | F1: Molto Buono | G1: Eccellente | H1: Valore
A2: T1_SE1 | B2: Ti senti sicuro nel scegliere un periodo storico che ti interessa? | F2: x | H2: =IF(C2="X",1)+IF(D2="X",2)+IF(E2="X",3)+IF(F2="X",4)+IF(G2="X",5) -> 4
A3: T1_SE2 | B3: Hai mai scelto da solo un argomento o un periodo storico che ti incuriosiva? | F3: x | H3: =IF(C3="X",1)+IF(D3="X",2)+IF(E3="X",3)+IF(F3="X",4)+IF(G3="X",5) -> 4
A4: T1_SE3 | B4: Ti senti più sicuro se ci sono immagini o suoni associati ai periodi da scegliere? | D4: x | H4: =IF(C4="X",1)+IF(D4="X",2)+IF(E4="X",3)+IF(F4="X",4)+IF(G4="X",5) -> 2
B5: Knowledge&Skills
A6: T1_KS1 | B6: Sai cosa significa scegliere un periodo storico? | E6: x | H6: =IF(C6="X",1)+IF(D6="X",2)+IF(E6="X",3)+IF(F6="X",4)+IF(G6="X",5) -> 3
A7: T1_KS2 | B7: Sai distinguere tra l'antico Egitto, Roma e il Medioevo? | E7: x | H7: =IF(C7="X",1)+IF(D7="X",2)+IF(E7="X",3)+IF(F7="X",4)+IF(G7="X",5) -> 3
B9: Self Efficacy
A10: T2_SE1 | B10: Ti senti a tuo agio nel cominciare una conversazione con qualcuno, anche se non lo conosci? | F10: x | H10: =IF(C10="X",1)+IF(D10="X",2)+IF(E10="X",3)+IF(F10="X",4)+IF(G10="X",5) -> 4
A11: T2_SE2 | B11: A volte ti blocchi quando devi iniziare a fare una domanda? | C11: x | H11: =IF(C11="X",1)+IF(D11="X",2)+IF(E11="X",3)+IF(F11="X",4)+IF(G11="X",5) -> 1
A12: T2_SE3 | B12: Ti senti sicuro quando devi fare una domanda su qualcosa che studi a scuola? | F12: x | H12: =IF(C12="X",1)+IF(D12="X",2)+IF(E12="X",3)+IF(F12="X",4)+IF(G12="X",5) -> 4
B13: Knowledge&Skills
A14: T2_KS1 | B14: Hai mai provato a fare domande a qualcuno (persona o sistema) per imparare qualcosa? | G14: x | H14: =IF(C14="X",1)+IF(D14="X",2)+IF(E14="X",3)+IF(F14="X",4)+IF(G14="X",5) -> 5
B15: Motivation
A16: T2_MOT1 | B16: Ti incuriosisce l’idea di poter parlare con un personaggio famoso del passato? | G16: x | H16: =IF(C16="X",1)+IF(D16="X",2)+IF(E16="X",3)+IF(F16="X",4)+IF(G16="X",5) -> 5
A17: T2_MOT2 | B17: Preferisci che il personaggio inizi a parlarti prima? | F17: x | H17: =IF(C17="X",1)+IF(D17="X",2)+IF(E17="X",3)+IF(F17="X",4)+IF(G17="X",5) -> 4
B19: Self Efficacy
A20: T3_SE1 | B20: Pensi di riuscire a portare avanti una conversazione facendo domande e ascoltando le risposte? | G20: x | H20: =IF(C20="X",1)+IF(D20="X",2)+IF(E20="X",3)+IF(F20="X",4)+IF(G20="X",5) -> 5
A21: T3_SE2 | B21: Ti è mai capitato di non sapere cosa dire dopo una prima domanda? | F21: x | H21: =IF(C21="X",1)+IF(D21="X",2)+IF(E21="X",3)+IF(F21="X",4)+IF(G21="X",5) -> 4
B22: Knowledge&Skills
A23: T3_KS1 | B23: Sai che tipo di domande fare per ottenere buone risposte? | F23: x | H23: =IF(C23="X",1)+IF(D23="X",2)+IF(E23="X",3)+IF(F23="X",4)+IF(G23="X",5) -> 4
A24: T3_KS2 | B24: Quando qualcuno ti spiega qualcosa, riesci a seguirlo senza perderti? | F24: x | H24: =IF(C24="X",1)+IF(D24="X",2)+IF(E24="X",3)+IF(F24="X",4)+IF(G24="X",5) -> 4
B25: Motivation
A26: T3_MOT1 | B26: Ti entusiasma l’idea di poter fare più domande per scoprire cose nuove? | G26: x | H26: =IF(C26="X",1)+IF(D26="X",2)+IF(E26="X",3)+IF(F26="X",4)+IF(G26="X",5) -> 5
A27: T3_MOT2 | B27: Ti fa piacere quando ottieni una risposta interessante? | F27: x | H27: =IF(C27="X",1)+IF(D27="X",2)+IF(E27="X",3)+IF(F27="X",4)+IF(G27="X",5) -> 4
B29: Knowledge&Skills
A30: T4_KS1 | B30: Sai come si fa a rispondere alle domande di un quiz? | G30: x | H30: =IF(C30="X",1)+IF(D30="X",2)+IF(E30="X",3)+IF(F30="X",4)+IF(G30="X",5) -> 5
B31: Personal Control
A32: T4_PC1 | B32: Ti senti capace di gestire il quiz da sola, senza aiuto? | F32: x | H32: =IF(C32="X",1)+IF(D32="X",2)+IF(E32="X",3)+IF(F32="X",4)+IF(G32="X",5) -> 4
A33: T4_PC2 | B33: Ti senti bravo con i quiz a risposta multipla? | F33: x | H33: =IF(C33="X",1)+IF(D33="X",2)+IF(E33="X",3)+IF(F33="X",4)+IF(G33="X",5) -> 4
A34: T4_PC3 | B34: Ti senti bravo con i quiz a tempo? | F34: x | H34: =IF(C34="X",1)+IF(D34="X",2)+IF(E34="X",3)+IF(F34="X",4)+IF(G34="X",5) -> 4
B35: Motivation
A36: T4_MOT1 | B36: Ti piace quando il quiz è come un gioco? | G36: x | H36: =IF(C36="X",1)+IF(D36="X",2)+IF(E36="X",3)+IF(F36="X",4)+IF(G36="X",5) -> 5
A37: T4_MOT2 | B37: Ti senti soddisfatto quando rispondi bene alle domande? | G37: x | H37: =IF(C37="X",1)+IF(D37="X",2)+IF(E37="X",3)+IF(F37="X",4)+IF(G37="X",5) -> 5
A38: T4_MOT3 | B38: Se sbagli una risposta, ti viene voglia di riprovare? | E38: x | H38: =IF(C38="X",1)+IF(D38="X",2)+IF(E38="X",3)+IF(F38="X",4)+IF(G38="X",5) -> 3
B40: Knowledge&Skills
A41: T5_KS1 | B41: Hai mai salvato o scritto qualcosa per ricordarlo meglio? | F41: x | H41: =IF(C41="X",1)+IF(D41="X",2)+IF(E41="X",3)+IF(F41="X",4)+IF(G41="X",5) -> 4
A42: T5_KS2 | B42: Ti è capitato di voler rileggere qualcosa che ti interessava? | G42: x | H42: =IF(C42="X",1)+IF(D42="X",2)+IF(E42="X",3)+IF(F42="X",4)+IF(G42="X",5) -> 5
B43: Personal Control
A44: T5_PC1 | B44: Ti capita di ricordarti dove hai messo o salvato delle informazioni? | E44: x | H44: =IF(C44="X",1)+IF(D44="X",2)+IF(E44="X",3)+IF(F44="X",4)+IF(G44="X",5) -> 3
...

Sheet Quest.Undici
B1: Self Efficacy | C1: Scarso | D1: Sufficiente | E1: Buono | F1: Molto Buono | G1: Eccellente | H1: Valore
A2: T1_SE1 | B2: Ti senti sicuro nel scegliere un periodo storico che ti interessa? | D2: x | H2: =IF(C2="X",1)+IF(D2="X",2)+IF(E2="X",3)+IF(F2="X",4)+IF(G2="X",5) -> 2
A3: T1_SE2 | B3: Hai mai scelto da solo un argomento o un periodo storico che ti incuriosiva? | C3: x | H3: =IF(C3="X",1)+IF(D3="X",2)+IF(E3="X",3)+IF(F3="X",4)+IF(G3="X",5) -> 1
A4: T1_SE3 | B4: Ti senti più sicuro se ci sono immagini o suoni associati ai periodi da scegliere? | F4: x | H4: =IF(C4="X",1)+IF(D4="X",2)+IF(E4="X",3)+IF(F4="X",4)+IF(G4="X",5) -> 4
B5: Knowledge&Skills
A6: T1_KS1 | B6: Sai cosa significa scegliere un periodo storico? | D6: x | H6: =IF(C6="X",1)+IF(D6="X",2)+IF(E6="X",3)+IF(F6="X",4)+IF(G6="X",5) -> 2
A7: T1_KS2 | B7: Sai distinguere tra l'antico Egitto, Roma e il Medioevo? | C7: x | H7: =IF(C7="X",1)+IF(D7="X",2)+IF(E7="X",3)+IF(F7="X",4)+IF(G7="X",5) -> 1
B9: Self Efficacy
A10: T2_SE1 | B10: Ti senti a tuo agio nel cominciare una conversazione con qualcuno, anche se non lo conosci? | C10: x | H10: =IF(C10="X",1)+IF(D10="X",2)+IF(E10="X",3)+IF(F10="X",4)+IF(G10="X",5) -> 1
A11: T2_SE2 | B11: A volte ti blocchi quando devi iniziare a fare una domanda? | C11: x | H11: =IF(C11="X",1)+IF(D11="X",2)+IF(E11="X",3)+IF(F11="X",4)+IF(G11="X",5) -> 1
A12: T2_SE3 | B12: Ti senti sicuro quando devi fare una domanda su qualcosa che studi a scuola? | D12: x | H12: =IF(C12="X",1)+IF(D12="X",2)+IF(E12="X",3)+IF(F12="X",4)+IF(G12="X",5) -> 2
B13: Knowledge&Skills
A14: T2_KS1 | B14: Hai mai provato a fare domande a qualcuno (persona o sistema) per imparare qualcosa? | C14: x | H14: =IF(C14="X",1)+IF(D14="X",2)+IF(E14="X",3)+IF(F14="X",4)+IF(G14="X",5) -> 1
B15: Motivation
A16: T2_MOT1 | B16: Ti incuriosisce l’idea di poter parlare con un personaggio famoso del passato? | G16: x | H16: =IF(C16="X",1)+IF(D16="X",2)+IF(E16="X",3)+IF(F16="X",4)+IF(G16="X",5) -> 5
A17: T2_MOT2 | B17: Preferisci che il personaggio inizi a parlarti prima? | F17: x | H17: =IF(C17="X",1)+IF(D17="X",2)+IF(E17="X",3)+IF(F17="X",4)+IF(G17="X",5) -> 4
B19: Self Efficacy
A20: T3_SE1 | B20: Pensi di riuscire a portare avanti una conversazione facendo domande e ascoltando le risposte? | F20: x | H20: =IF(C20="X",1)+IF(D20="X",2)+IF(E20="X",3)+IF(F20="X",4)+IF(G20="X",5) -> 4
A21: T3_SE2 | B21: Ti è mai capitato di non sapere cosa dire dopo una prima domanda? | D21: x | H21: =IF(C21="X",1)+IF(D21="X",2)+IF(E21="X",3)+IF(F21="X",4)+IF(G21="X",5) -> 2
B22: Knowledge&Skills
A23: T3_KS1 | B23: Sai che tipo di domande fare per ottenere buone risposte? | D23: x | H23: =IF(C23="X",1)+IF(D23="X",2)+IF(E23="X",3)+IF(F23="X",4)+IF(G23="X",5) -> 2
A24: T3_KS2 | B24: Quando qualcuno ti spiega qualcosa, riesci a seguirlo senza perderti? | D24: x | H24: =IF(C24="X",1)+IF(D24="X",2)+IF(E24="X",3)+IF(F24="X",4)+IF(G24="X",5) -> 2
B25: Motivation
A26: T3_MOT1 | B26: Ti entusiasma l’idea di poter fare più domande per scoprire cose nuove? | G26: x | H26: =IF(C26="X",1)+IF(D26="X",2)+IF(E26="X",3)+IF(F26="X",4)+IF(G26="X",5) -> 5
A27: T3_MOT2 | B27: Ti fa piacere quando ottieni una risposta interessante? | F27: x | H27: =IF(C27="X",1)+IF(D27="X",2)+IF(E27="X",3)+IF(F27="X",4)+IF(G27="X",5) -> 4
B29: Knowledge&Skills
A30: T4_KS1 | B30: Sai come si fa a rispondere alle domande di un quiz? | E30: x | H30: =IF(C30="X",1)+IF(D30="X",2)+IF(E30="X",3)+IF(F30="X",4)+IF(G30="X",5) -> 3
B31: Personal Control
A32: T4_PC1 | B32: Ti senti capace di gestire il quiz da sola, senza aiuto? | E32: x | H32: =IF(C32="X",1)+IF(D32="X",2)+IF(E32="X",3)+IF(F32="X",4)+IF(G32="X",5) -> 3
A33: T4_PC2 | B33: Ti senti bravo con i quiz a risposta multipla? | D33: x | H33: =IF(C33="X",1)+IF(D33="X",2)+IF(E33="X",3)+IF(F33="X",4)+IF(G33="X",5) -> 2
A34: T4_PC3 | B34: Ti senti bravo con i quiz a tempo? | D34: x | H34: =IF(C34="X",1)+IF(D34="X",2)+IF(E34="X",3)+IF(F34="X",4)+IF(G34="X",5) -> 2
B35: Motivation
A36: T4_MOT1 | B36: Ti piace quando il quiz è come un gioco? | E36: x | H36: =IF(C36="X",1)+IF(D36="X",2)+IF(E36="X",3)+IF(F36="X",4)+IF(G36="X",5) -> 3
A37: T4_MOT2 | B37: Ti senti soddisfatto quando rispondi bene alle domande? | G37: x | H37: =IF(C37="X",1)+IF(D37="X",2)+IF(E37="X",3)+IF(F37="X",4)+IF(G37="X",5) -> 5
A38: T4_MOT3 | B38: Se sbagli una risposta, ti viene voglia di riprovare? | F38: x | H38: =IF(C38="X",1)+IF(D38="X",2)+IF(E38="X",3)+IF(F38="X",4)+IF(G38="X",5) -> 4
B40: Knowledge&Skills
A41: T5_KS1 | B41: Hai mai salvato o scritto qualcosa per ricordarlo meglio? | E41: x | H41: =IF(C41="X",1)+IF(D41="X",2)+IF(E41="X",3)+IF(F41="X",4)+IF(G41="X",5) -> 3
A42: T5_KS2 | B42: Ti è capitato di voler rileggere qualcosa che ti interessava? | D42: x | H42: =IF(C42="X",1)+IF(D42="X",2)+IF(E42="X",3)+IF(F42="X",4)+IF(G42="X",5) -> 2
B43: Personal Control
A44: T5_PC1 | B44: Ti capita di ricordarti dove hai messo o salvato delle informazioni? | E44: x | H44: =IF(C44="X",1)+IF(D44="X",2)+IF(E44="X",3)+IF(F44="X",4)+IF(G44="X",5) -> 3
...

Sheet Quest.MrClark
B1: Knowledge&Skills | C1: Scarso | D1: Sufficiente | E1: Buono | F1: Molto Buono | G1: Eccellente | H1: Valore
A2: T5_KS1 | B2: Hai mai salvato o scritto qualcosa per ricordarlo meglio? | F2: x | H2: =IF(C2="X",1)+IF(D2="X",2)+IF(E2="X",3)+IF(F2="X",4)+IF(G2="X",5) -> 4
A3: T5_KS2 | B3: Ti è capitato di voler rileggere qualcosa che ti interessava? | G3: x | H3: =IF(C3="X",1)+IF(D3="X",2)+IF(E3="X",3)+IF(F3="X",4)+IF(G3="X",5) -> 5
B4: Personal Control
A5: T5_PC1 | B5: Ti capita di ricordarti dove hai messo o salvato delle informazioni? | F5: x | H5: =IF(C5="X",1)+IF(D5="X",2)+IF(E5="X",3)+IF(F5="X",4)+IF(G5="X",5) -> 4
A6: T5_PC2 | B6: Ti senti in grado di decidere quali cose sono importanti da salvare? | G6: x | H6: =IF(C6="X",1)+IF(D6="X",2)+IF(E6="X",3)+IF(F6="X",4)+IF(G6="X",5) -> 5
B8: Self Efficacy
A9: T8_SE1 | B9: Quanto ti senti sicuro nel proporre o affrontare attività legate allo studio della storia, anche in autonomia? | F9: x | H9: =IF(C9="X",1)+IF(D9="X",2)+IF(E9="X",3)+IF(F9="X",4)+IF(G9="X",5) -> 4
A10: T8_SE2 | B10: Se avessi uno strumento digitale per studiare o insegnare storia, pensi che ti sentiresti in grado di usarlo senza difficoltà? | F10: x | H10: =IF(C10="X",1)+IF(D10="X",2)+IF(E10="X",3)+IF(F10="X",4)+IF(G10="X",5) -> 4
B11: Knowledge&Skills
A12: T8_KS1 | B12: Quando lavori o fai lavorare su un argomento storico, i materiali e le istruzioni risultano generalmente chiari e comprensibili senza bisogno di ulteriori chiarimenti? | D12: x | H12: =IF(C12="X",1)+IF(D12="X",2)+IF(E12="X",3)+IF(F12="X",4)+IF(G12="X",5) -> 2
B13: Personal Control
A14: T8_PC1 | B14: Quanto è importante per te poter decidere quando e come svolgere attività legate alla storia (come studio, domande, esercizi)? | F14: x | H14: =IF(C14="X",1)+IF(D14="X",2)+IF(E14="X",3)+IF(F14="X",4)+IF(G14="X",5) -> 4
A15: T8_PC2 | B15: Ti piacerebbe avere la possibilità di adattare o personalizzare il contenuto o il modo in cui lavori con la storia, in base alle tue esigenze? | G15: x | H15: =IF(C15="X",1)+IF(D15="X",2)+IF(E15="X",3)+IF(F15="X",4)+IF(G15="X",5) -> 5
B16: Motivation
A17: T8_MOT1 | B17: Ti interesserebbe uno strumento che renda lo studio o l’insegnamento della storia più coinvolgente e organizzato? | G17: x | H17: =IF(C17="X",1)+IF(D17="X",2)+IF(E17="X",3)+IF(F17="X",4)+IF(G17="X",5) -> 5
A18: T8_MOT2 | B18: Quanto pensi che vedere i propri progressi o risultati possa motivarti a continuare a usare uno strumento digitale per la storia? | F18: x | H18: =IF(C18="X",1)+IF(D18="X",2)+IF(E18="X",3)+IF(F18="X",4)+IF(G18="X",5) -> 4
B20: Self Efficacy
A21: T9_SE1 | B21: Ti senti sicuro nel gestire in autonomia la creazione e l’organizzazione di una classe, anche in contesti non tradizionali? | F21: x | H21: =IF(C21="X",1)+IF(D21="X",2)+IF(E21="X",3)+IF(F21="X",4)+IF(G21="X",5) -> 4
A22: T9_SE2 | B22: Se qualcosa non va come previsto nell’organizzazione di una classe, ti senti in grado di trovare soluzioni e ripartire senza supporto esterno? | F22: x | H22: =IF(C22="X",1)+IF(D22="X",2)+IF(E22="X",3)+IF(F22="X",4)+IF(G22="X",5) -> 4
B23: Knowledge&Skills
A24: T9_KS1 | B24: Quando organizzi una classe o un’attività didattica, trovi facilmente le indicazioni o i riferimenti di cui hai bisogno? | E24: x | H24: =IF(C24="X",1)+IF(D24="X",2)+IF(E24="X",3)+IF(F24="X",4)+IF(G24="X",5) -> 3
B25: Personal Control
A26: T9_PC1 | B26: Hai la possibilità concreta di decidere tempi, modalità e impostazioni delle attività nella tua classe secondo il tuo metodo di lavoro? | E26: x | H26: =IF(C26="X",1)+IF(D26="X",2)+IF(E26="X",3)+IF(F26="X",4)+IF(G26="X",5) -> 3
A27: T9_PC2 | B27: Riesci a gestire liberamente l’attivazione, la sospensione o la chiusura di attività e progetti nella tua classe? | D27: x | H27: =IF(C27="X",1)+IF(D27="X",2)+IF(E27="X",3)+IF(F27="X",4)+IF(G27="X",5) -> 2
B28: Motivation
A29: T9_MOT1 | B29: Avere il pieno controllo sull’organizzazione delle attività didattiche ti fa sentire più motivato e sereno nel tuo lavoro? | F29: x | H29: =IF(C29="X",1)+IF(D29="X",2)+IF(E29="X",3)+IF(F29="X",4)+IF(G29="X",5) -> 4
A30: T9_MOT2 | B30: Personalizzare la gestione della classe secondo il tuo stile e quello dei tuoi studenti ti aiuta a sentirti più coinvolto? | G30: x | H30: =IF(C30="X",1)+IF(D30="X",2)+IF(E30="X",3)+IF(F30="X",4)+IF(G30="X",5) -> 5
B32: Self Efficacy
A33: T10_SE1 | B33: Ti senti sicuro nell’assegnare domande o compiti alla classe come parte del tuo lavoro quotidiano? | F33: x | H33: =IF(C33="X",1)+IF(D33="X",2)+IF(E33="X",3)+IF(F33="X",4)+IF(G33="X",5) -> 4
A34: T10_SE2 | B34: Quando decidi di proporre una nuova attività o domanda, ti senti in grado di organizzarla senza difficoltà? | E34: x | H34: =IF(C34="X",1)+IF(D34="X",2)+IF(E34="X",3)+IF(F34="X",4)+IF(G34="X",5) -> 3
B35: Knowledge&Skills
A36: T10_KS1 | B36: Hai a disposizione riferimenti, idee o materiali che ti aiutano a scegliere e formulare le domande giuste per i tuoi studenti? | E36: x | H36: =IF(C36="X",1)+IF(D36="X",2)+IF(E36="X",3)+IF(F36="X",4)+IF(G36="X",5) -> 3
B37: Personal Control
A38: T10_PC1 | B38: Ti senti libero di scegliere quali domande proporre alla classe e in quali momenti farlo? | F38: x | H38: =IF(C38="X",1)+IF(D38="X",2)+IF(E38="X",3)+IF(F38="X",4)+IF(G38="X",5) -> 4
A39: T10_PC2 | B39: Quanto è semplice per te modificare o adattare una domanda già proposta, se le esigenze della classe cambiano? | D39: x | H39: =IF(C39="X",1)+IF(D39="X",2)+IF(E39="X",3)+IF(F39="X",4)+IF(G39="X",5) -> 2
B40: Motivation
A41: T10_MOT1 | B41: Proporre domande o attività nella tua didattica ti aiuta a rendere le lezioni più stimolanti e partecipate? | F41: x | H41: =IF(C41="X",1)+IF(D41="X",2)+IF(E41="X",3)+IF(F41="X",4)+IF(G41="X",5) -> 4
A42: T10_MOT2 | B42: Quanto è importante per te poter adattare le domande o le attività ai diversi bisogni dei tuoi studenti? | G42: x | H42: =IF(C42="X",1)+IF(D42="X",2)+IF(E42="X",3)+IF(F42="X",4)+IF(G42="X",5) -> 5
B44: Self Efficacy
...

Sheet Quest.Erica
B1: Self Efficacy | C1: Scarso | D1: Sufficiente | E1: Buono | F1: Molto Buono | G1: Eccellente | H1: Valore
A2: T1_SE1 | B2: Ti senti sicuro nel scegliere un periodo storico che ti interessa? | D2: x | H2: =IF(C2="X",1)+IF(D2="X",2)+IF(E2="X",3)+IF(F2="X",4)+IF(G2="X",5) -> 2
A3: T1_SE2 | B3: Hai mai scelto da solo un argomento o un periodo storico che ti incuriosiva? | E3: x | H3: =IF(C3="X",1)+IF(D3="X",2)+IF(E3="X",3)+IF(F3="X",4)+IF(G3="X",5) -> 3
A4: T1_SE3 | B4: Ti senti più sicuro se ci sono immagini o suoni associati ai periodi da scegliere? | G4: x | H4: 5
B5: Knowledge&Skills
A6: T1_KS1 | B6: Sai cosa significa scegliere un periodo storico? | C6: x | H6: =IF(C6="X",1)+IF(D6="X",2)+IF(E6="X",3)+IF(F6="X",4)+IF(G6="X",5) -> 1
A7: T1_KS2 | B7: Sai distinguere tra l'antico Egitto, Roma e il Medioevo? | C7: x | H7: =IF(C7="X",1)+IF(D7="X",2)+IF(E7="X",3)+IF(F7="X",4)+IF(G7="X",5) -> 1
B9: Self Efficacy
A10: T2_SE1 | B10: Ti senti a tuo agio nel cominciare una conversazione con qualcuno, anche se non lo conosci? | C10: x | H10: =IF(C10="X",1)+IF(D10="X",2)+IF(E10="X",3)+IF(F10="X",4)+IF(G10="X",5) -> 1
A11: T2_SE2 | B11: A volte ti blocchi quando devi iniziare a fare una domanda? | E11: x | H11: =IF(C11="X",1)+IF(D11="X",2)+IF(E11="X",3)+IF(F11="X",4)+IF(G11="X",5) -> 3
A12: T2_SE3 | B12: Ti senti sicuro quando devi fare una domanda su qualcosa che studi a scuola? | D12: x | H12: =IF(C12="X",1)+IF(D12="X",2)+IF(E12="X",3)+IF(F12="X",4)+IF(G12="X",5) -> 2
B13: Knowledge&Skills
A14: T2_KS1 | B14: Hai mai provato a fare domande a qualcuno (persona o sistema) per imparare qualcosa? | D14: x | H14: =IF(C14="X",1)+IF(D14="X",2)+IF(E14="X",3)+IF(F14="X",4)+IF(G14="X",5) -> 2
B15: Motivation
A16: T2_MOT1 | B16: Ti incuriosisce l’idea di poter parlare con un personaggio famoso del passato? | G16: x | H16: =IF(C16="X",1)+IF(D16="X",2)+IF(E16="X",3)+IF(F16="X",4)+IF(G16="X",5) -> 5
A17: T2_MOT2 | B17: Preferisci che il personaggio inizi a parlarti prima? | G17: x | H17: =IF(C17="X",1)+IF(D17="X",2)+IF(E17="X",3)+IF(F17="X",4)+IF(G17="X",5) -> 5
B19: Self Efficacy
A20: T3_SE1 | B20: Pensi di riuscire a portare avanti una conversazione facendo domande e ascoltando le risposte? | E20: x | H20: =IF(C20="X",1)+IF(D20="X",2)+IF(E20="X",3)+IF(F20="X",4)+IF(G20="X",5) -> 3
A21: T3_SE2 | B21: Ti è mai capitato di non sapere cosa dire dopo una prima domanda? | D21: x | H21: =IF(C21="X",1)+IF(D21="X",2)+IF(E21="X",3)+IF(F21="X",4)+IF(G21="X",5) -> 2
B22: Knowledge&Skills
A23: T3_KS1 | B23: Sai che tipo di domande fare per ottenere buone risposte? | C23: x | H23: =IF(C23="X",1)+IF(D23="X",2)+IF(E23="X",3)+IF(F23="X",4)+IF(G23="X",5) -> 1
A24: T3_KS2 | B24: Quando qualcuno ti spiega qualcosa, riesci a seguirlo senza perderti? | F24: x | H24: =IF(C24="X",1)+IF(D24="X",2)+IF(E24="X",3)+IF(F24="X",4)+IF(G24="X",5) -> 4
B25: Motivation
A26: T3_MOT1 | B26: Ti entusiasma l’idea di poter fare più domande per scoprire cose nuove? | G26: x | H26: =IF(C26="X",1)+IF(D26="X",2)+IF(E26="X",3)+IF(F26="X",4)+IF(G26="X",5) -> 5
A27: T3_MOT2 | B27: Ti fa piacere quando ottieni una risposta interessante? | F27: x | H27: =IF(C27="X",1)+IF(D27="X",2)+IF(E27="X",3)+IF(F27="X",4)+IF(G27="X",5) -> 4
B29: Knowledge&Skills
A30: T4_KS1 | B30: Sai come si fa a rispondere alle domande di un quiz? | E30: x | H30: =IF(C30="X",1)+IF(D30="X",2)+IF(E30="X",3)+IF(F30="X",4)+IF(G30="X",5) -> 3
B31: Personal Control
A32: T4_PC1 | B32: Ti senti capace di gestire il quiz da sola, senza aiuto? | E32: x | H32: =IF(C32="X",1)+IF(D32="X",2)+IF(E32="X",3)+IF(F32="X",4)+IF(G32="X",5) -> 3
A33: T4_PC2 | B33: Ti senti bravo con i quiz a risposta multipla? | F33: x | H33: =IF(C33="X",1)+IF(D33="X",2)+IF(E33="X",3)+IF(F33="X",4)+IF(G33="X",5) -> 4
A34: T4_PC3 | B34: Ti senti bravo con i quiz a tempo? | D34: x | H34: =IF(C34="X",1)+IF(D34="X",2)+IF(E34="X",3)+IF(F34="X",4)+IF(G34="X",5) -> 2
B35: Motivation
A36: T4_MOT1 | B36: Ti piace quando il quiz è come un gioco? | G36: x | H36: =IF(C36="X",1)+IF(D36="X",2)+IF(E36="X",3)+IF(F36="X",4)+IF(G36="X",5) -> 5
A37: T4_MOT2 | B37: Ti senti soddisfatto quando rispondi bene alle domande? | G37: x | H37: =IF(C37="X",1)+IF(D37="X",2)+IF(E37="X",3)+IF(F37="X",4)+IF(G37="X",5) -> 5
A38: T4_MOT3 | B38: Se sbagli una risposta, ti viene voglia di riprovare? | F38: x | H38: =IF(C38="X",1)+IF(D38="X",2)+IF(E38="X",3)+IF(F38="X",4)+IF(G38="X",5) -> 4
B40: Knowledge&Skills
A41: T5_KS1 | B41: Hai mai salvato o scritto qualcosa per ricordarlo meglio? | F41: x | H41: =IF(C41="X",1)+IF(D41="X",2)+IF(E41="X",3)+IF(F41="X",4)+IF(G41="X",5) -> 4
A42: T5_KS2 | B42: Ti è capitato di voler rileggere qualcosa che ti interessava? | F42: x | H42: =IF(C42="X",1)+IF(D42="X",2)+IF(E42="X",3)+IF(F42="X",4)+IF(G42="X",5) -> 4
B43: Personal Control
A44: T5_PC1 | B44: Ti capita di ricordarti dove hai messo o salvato delle informazioni? | E44: x | H44: =IF(C44="X",1)+IF(D44="X",2)+IF(E44="X",3)+IF(F44="X",4)+IF(G44="X",5) -> 3
...

Sheet Quest.Joyce
C1: Scarso | D1: Sufficiente | E1: Buono | F1: Molto Buono | G1: Eccellente | H1: Valore
B2: Personal Control
A3: T12_PC1 | B3: Hai la possibilità di scegliere liberamente quando e come informarti sull’andamento scolastico di tuo/a figlio/a? | E3: x | H3: =IF(C3="X",1)+IF(D3="X",2)+IF(E3="X",3)+IF(F3="X",4)+IF(G3="X",5) -> 3
A4: T12_PC2 | B4: Riesci con facilità a restare aggiornata sui suoi progressi scolastici, oppure trovi difficoltà nel farlo con continuità? | D4: x | H4: =IF(C4="X",1)+IF(D4="X",2)+IF(E4="X",3)+IF(F4="X",4)+IF(G4="X",5) -> 2
B5: Motivation
A6: T12_MOT1 | B6: Ti piacerebbe essere più coinvolta nel percorso scolastico di tuo/a figlio/a, se avessi strumenti più semplici e accessibili? | G6: x | H6: =IF(C6="X",1)+IF(D6="X",2)+IF(E6="X",3)+IF(F6="X",4)+IF(G6="X",5) -> 5
A7: T12_MOT2 | B7: Ti sentiresti più motivata a supportare tuo/a figlio/a se avessi una visione più chiara dei suoi miglioramenti o delle sue difficoltà? | F7: x | H7: =IF(C7="X",1)+IF(D7="X",2)+IF(E7="X",3)+IF(F7="X",4)+IF(G7="X",5) -> 4

Sheet MEDIE
C1: Valore
A2: T1_SE1 | B2: Ti senti sicuro nel scegliere un periodo storico che ti interessa? | C2: =AVERAGE(Quest.Dustin!H2,Quest.Undici!H2,Quest.Erica!H2) -> 2.6666667 | D2: MEDIA DELLE RISPOSTE
A3: T1_SE2 | B3: Hai mai scelto da solo un argomento o un periodo storico che ti incuriosiva? | C3: =AVERAGE(Quest.Dustin!H3,Quest.Undici!H3,Quest.Erica!H3) -> 2.6666667 | D3: MEDIA DELLE RISPOSTE
A4: T1_SE3 | B4: Ti senti più sicuro se ci sono immagini o suoni associati ai periodi da scegliere? | C4: =AVERAGE(Quest.Dustin!H4,Quest.Undici!H4,Quest.Erica!H4) -> 3.6666667 | D4: MEDIA DELLE RISPOSTE
C5: =AVERAGE(C2:C4) -> 3 | D5: MEDIA TRA I VALORI MEDI RELATIVI A QUELL'ABILITA' | E5: Self Efficacy
A6: T1_KS1 | B6: Sai cosa significa scegliere un periodo storico? | C6: =AVERAGE(Quest.Dustin!H6,Quest.Undici!H6,Quest.Erica!H6) -> 2 | D6: MEDIA DELLE RISPOSTE
A7: T1_KS2 | B7: Sai distinguere tra l'antico Egitto, Roma e il Medioevo? | C7: =AVERAGE(Quest.Dustin!H7,Quest.Undici!H7,Quest.Erica!H7) -> 1.6666667 | D7: MEDIA DELLE RISPOSTE
C8: =AVERAGE(C6:C7) -> 1.8333333 | D8: MEDIA TRA I VALORI MEDI RELATIVI A QUELL'ABILITA' | E8: Knowledge&Skills
A9: T2_SE1 | B9: Ti senti a tuo agio nel cominciare una conversazione con qualcuno, anche se non lo conosci? | C9: =AVERAGE(Quest.Dustin!H10,Quest.Undici!H10,Quest.Erica!H10) -> 2 | D9: MEDIA DELLE RISPOSTE
A10: T2_SE2 | B10: A volte ti blocchi quando devi iniziare a fare una domanda? | C10: =AVERAGE(Quest.Dustin!H11,Quest.Undici!H11,Quest.Erica!H11) -> 1.6666667 | D10: MEDIA DELLE RISPOSTE
A11: T2_SE3 | B11: Ti senti sicuro quando devi fare una domanda su qualcosa che studi a scuola? | C11: =AVERAGE(Quest.Dustin!H12,Quest.Undici!H12,Quest.Erica!H12) -> 2.6666667 | D11: MEDIA DELLE RISPOSTE
C12: =AVERAGE(C9:C11) -> 2.1111111 | D12: MEDIA TRA I VALORI MEDI RELATIVI A QUELL'ABILITA' | E12: Self Efficacy
A13: T2_KS1 | B13: Hai mai provato a fare domande a qualcuno (persona o sistema) per imparare qualcosa? | C13: =AVERAGE(Quest.Dustin!H14,Quest.Undici!H14,Quest.Erica!H14) -> 2.6666667 | D13: MEDIA DELLE RISPOSTE
C14: =AVERAGE(C13) -> 2.6666667 | D14: MEDIA TRA I VALORI MEDI RELATIVI A QUELL'ABILITA' | E14: Knowledge&Skills
A15: T2_MOT1 | B15: Ti incuriosisce l’idea di poter parlare con un personaggio famoso del passato? | C15: =AVERAGE(Quest.Dustin!H16,Quest.Undici!H16,Quest.Erica!H16) -> 5 | D15: MEDIA DELLE RISPOSTE
A16: T2_MOT2 | B16: Preferisci che il personaggio inizi a parlarti prima? | C16: =AVERAGE(Quest.Dustin!H17,Quest.Undici!H17,Quest.Erica!H17) -> 4.3333333 | D16: MEDIA DELLE RISPOSTE
C17: =AVERAGE(C15:C16) -> 4.6666667 | D17: MEDIA TRA I VALORI MEDI RELATIVI A QUELL'ABILITA' | E17: Motivation
A18: T3_SE1 | B18: Pensi di riuscire a portare avanti una conversazione facendo domande e ascoltando le risposte? | C18: =AVERAGE(Quest.Dustin!H20,Quest.Undici!H20,Quest.Erica!H20) -> 4 | D18: MEDIA DELLE RISPOSTE
A19: T3_SE2 | B19: Ti è mai capitato di non sapere cosa dire dopo una prima domanda? | C19: =AVERAGE(Quest.Dustin!H21,Quest.Undici!H21,Quest.Erica!H21) -> 2.6666667 | D19: MEDIA DELLE RISPOSTE
C20: =AVERAGE(C18:C19) -> 3.3333333 | D20: MEDIA TRA I VALORI MEDI RELATIVI A QUELL'ABILITA' | E20: Self Efficacy
A21: T3_KS1 | B21: Sai che tipo di domande fare per ottenere buone risposte? | C21: =AVERAGE(Quest.Dustin!H23,Quest.Undici!H23,Quest.Erica!H23) -> 2.3333333 | D21: MEDIA DELLE RISPOSTE
A22: T3_KS2 | B22: Quando qualcuno ti spiega qualcosa, riesci a seguirlo senza perderti? | C22: =AVERAGE(Quest.Dustin!H24,Quest.Undici!H24,Quest.Erica!H24) -> 3.3333333 | D22: MEDIA DELLE RISPOSTE
C23: =AVERAGE(C21:C22) -> 2.8333333 | D23: MEDIA TRA I VALORI MEDI RELATIVI A QUELL'ABILITA' | E23: Knowledge&Skills
A24: T3_MOT1 | B24: Ti entusiasma l’idea di poter fare più domande per scoprire cose nuove? | C24: =AVERAGE(Quest.Dustin!H26,Quest.Undici!H26,Quest.Erica!H26) -> 5 | D24: MEDIA DELLE RISPOSTE
A25: T3_MOT2 | B25: Ti fa piacere quando ottieni una risposta interessante? | C25: =AVERAGE(Quest.Dustin!H27,Quest.Undici!H27,Quest.Erica!H27) -> 4 | D25: MEDIA DELLE RISPOSTE
C26: =AVERAGE(C24:C25) -> 4.5 | D26: MEDIA TRA I VALORI MEDI RELATIVI A QUELL'ABILITA' | E26: Motivation
A27: T4_KS1 | B27: Sai come si fa a rispondere alle domande di un quiz? | C27: =AVERAGE(Quest.Dustin!H30,Quest.Undici!H30,Quest.Erica!H30) -> 3.6666667 | D27: MEDIA DELLE RISPOSTE
C28: =AVERAGE(C27) -> 3.6666667 | D28: MEDIA TRA I VALORI MEDI RELATIVI A QUELL'ABILITA' | E28: Knowledge&Skills
A29: T4_PC1 | B29: Ti senti capace di gestire il quiz da sola, senza aiuto? | C29: =AVERAGE(Quest.Dustin!H32,Quest.Undici!H32,Quest.Erica!H32) -> 3.3333333 | D29: MEDIA DELLE RISPOSTE
A30: T4_PC2 | B30: Ti senti bravo con i quiz a risposta multipla? | C30: =AVERAGE(Quest.Dustin!H33,Quest.Undici!H33,Quest.Erica!H33) -> 3.3333333 | D30: MEDIA DELLE RISPOSTE
A31: T4_PC3 | B31: Ti senti bravo con i quiz a tempo? | C31: =AVERAGE(Quest.Dustin!H34,Quest.Undici!H34,Quest.Erica!H34) -> 2.6666667 | D31: MEDIA DELLE RISPOSTE
C32: =AVERAGE(C29:C31) -> 3.1111111 | D32: MEDIA TRA I VALORI MEDI RELATIVI A QUELL'ABILITA' | E32: Personal Control
A33: T4_MOT1 | B33: Ti piace quando il quiz è come un gioco? | C33: =AVERAGE(Quest.Dustin!H36,Quest.Undici!H36,Quest.Erica!H36) -> 4.3333333 | D33: MEDIA DELLE RISPOSTE
A34: T4_MOT2 | B34: Ti senti soddisfatto quando rispondi bene alle domande? | C34: =AVERAGE(Quest.Dustin!H37,Quest.Undici!H37,Quest.Erica!H37) -> 5 | D34: MEDIA DELLE RISPOSTE
A35: T4_MOT3 | B35: Se sbagli una risposta, ti viene voglia di riprovare? | C35: =AVERAGE(Quest.Dustin!H38,Quest.Undici!H38,Quest.Erica!H38) -> 3.6666667 | D35: MEDIA DELLE RISPOSTE
C36: =AVERAGE(C33:C35) -> 4.3333333 | D36: MEDIA TRA I VALORI MEDI RELATIVI A QUELL'ABILITA' | E36: Motivation
A37: T5_KS1 | B37: Hai mai salvato o scritto qualcosa per ricordarlo meglio? | C37: =AVERAGE(Quest.Dustin!H41,Quest.Undici!H41,Quest.Erica!H41,Quest.MrClark!H3) -> 4 | D37: MEDIA DELLE RISPOSTE
A38: T5_KS2 | B38: Ti è capitato di voler rileggere qualcosa che ti interessava? | C38: =AVERAGE(Quest.Dustin!H42,Quest.Undici!H42,Quest.Erica!H42,Quest.MrClark!H42) -> 4 | D38: MEDIA DELLE RISPOSTE
C39: =AVERAGE(C37:C38) -> 4 | D39: MEDIA TRA I VALORI MEDI RELATIVI A QUELL'ABILITA' | E39: Knowledge&Skills
A40: T5_PC1 | B40: Ti capita di ricordarti dove hai messo o salvato delle informazioni? | C40: =AVERAGE(Quest.Dustin!H44,Quest.Undici!H44,Quest.Erica!H44,Quest.MrClark!H5) -> 3.25 | D40: MEDIA DELLE RISPOSTE
...

Sheet TabRisultati
A1: Task | B1: ISE | C1: IKS | D1: IPC | E1: IMOT
A2: T1 - Selezionare un periodo storico | B2: =MEDIE!C5 -> 3 | C2: =MEDIE!C8 -> 1.8333333
A3: T2 - Avviare una conversazione | B3: =MEDIE!C12 -> 2.1111111 | C3: =MEDIE!C14 -> 2.6666667 | E3: =MEDIE!C17 -> 4.6666667
A4: T3 - Condurre una conversazione con un personaggio | B4: =MEDIE!C20 -> 3.3333333 | C4: =MEDIE!C23 -> 2.8333333 | E4: =MEDIE!C26 -> 4.5
A5: T4 - Partecipare a quiz | C5: =MEDIE!C28 -> 3.6666667 | D5: =MEDIE!C32 -> 3.1111111 | E5: =MEDIE!C36 -> 4.3333333
A6: T5 - Salvare o rivedere una conversazione utile | C6: =MEDIE!C39 -> 4 | D6: =MEDIE!C42 -> 3.25
A7: T6 - Condividere una conversazione con compagni o insegnanti | B7: =MEDIE!C46 -> 2.5555556 | E7: =MEDIE!C49 -> 3
A8: T7 - Ricevere feedback e premi virtuali | C8: =MEDIE!C51 -> 3 | D8: =MEDIE!C54 -> 2.8333333 | E8: =MEDIE!C58 -> 4.5555556
A9: T8 - Visualizzare le domande assegnate dall'insegnante | B9: =MEDIE!C61 -> 3.5 | C9: =MEDIE!C63 -> 1.5 | D9: =MEDIE!C66 -> 4.25 | E9: =MEDIE!C69 -> 4.5
A10: T9 - Creare una classe virtuale | B10: =MEDIE!C72 -> 4 | C10: =MEDIE!C74 -> 3 | D10: =MEDIE!C77 -> 2.5 | E10: =MEDIE!C80 -> 4.5
A11: T10 - Assegnare domande alla classe | B11: =MEDIE!C83 -> 3.5 | C11: =MEDIE!C85 -> 3 | D11: =MEDIE!C88 -> 3 | E11: =MEDIE!C91 -> 4.5
A12: T11 - Partecipare ad una classe virtuale | B12: =MEDIE!C92 -> 3.5 | C12: =MEDIE!C95 -> 3 | D12: =MEDIE!C98 -> 3.375 | E12: =MEDIE!C101 -> 4.25
A13: T12 - Seguire lo studio del figlio | D13: =MEDIE!C104 -> 2.5 | E13: =MEDIE!C107 -> 4.5
